Workbook
Name Type: '[1]Service Marketing Plan'!#REF!
Name Type: '[2]Business Meeting Agenda'!#REF!

Sheet EXAMPLE Multi Project Dashboard
B2: Multiple Project Dashboard Tracking Template Example
B3: DELIVERY TIMELINE & RESOURCES
B7: PROJECT FINANCIALS
B10: RISK ANALYSIS
B15: OPEN & PENDING ACTIONS
B20: PROJECT REPORT
B22: PROJECT NAME | C22: SCHEDULE | D22: BUDGET | E22: RESOURCES | F22: RISKS | G22: ISSUES | H22: COMMENTS
B23: Project A
B24: Project B
B25: Project C
B26: Project D
B27: Project E
B28: Project F
B29: Project G
B30: Project H
B31: Project J
B32: Project K
B33: Project L
B34: Project M
... B38: DASHBOARD DATA
B39: PROJECT NAME | C39: TIMELINE | G39: NUMBER OF TEAM MEMBERS | H39: BUDGET | K39: RISKS | N39: OPEN | P39: PENDING ACTIONS
C40: CALENDAR | D40: BEGIN | E40: FINISH | F40: # of DAYS | H40: PROJECTED | I40: ACTUAL | J40: REMAINDER | K40: HIGH | L40: MEDIUM | M40: LOW | N40: ISSUES | O40: REVISIONS
B41: Project A | C41: 45778 | D41: 45782 | E41: 45839 | F41: =E41-D41 -> 57 | G41: 10 | H41: 1000000 | I41: 880000 | J41: =(H41-I41) -> 120000 | K41: 1 | L41: 0 | M41: 4 | N41: 2 | O41: 0 | P41: 4
B42: Project B | C42: 45809 | D42: 45787 | E42: 45879 | F42: =E42-D42 -> 92 | G42: 5 | H42: 900000 | I42: 920000 | J42: =(H42-I42) -> -20000 | K42: 2 | L42: 3 | M42: 5 | N42: 1 | O42: 2 | P42: 3
B43: Project C | C43: 45839 | D43: 45818 | E43: 46082 | F43: =E43-D43 -> 264 | G43: 10 | H43: 860000 | I43: 850000 | J43: =(H43-I43) -> 10000 | K43: 3 | L43: 4 | M43: 3 | N43: 2 | O43: 1 | P43: 2
B44: Project D | C44: 45870 | D44: 45830 | E44: 45873 | F44: =E44-D44 -> 43 | G44: 5 | H44: 1000000 | I44: 998050 | J44: =(H44-I44) -> 1950 | K44: 5 | L44: 8 | M44: 1 | N44: 1 | O44: 0 | P44: 0
B45: Project E | C45: 45901 | D45: 45852 | E45: 45962 | F45: =E45-D45 -> 110 | G45: 10 | H45: 294000 | I45: 280000 | J45: =(H45-I45) -> 14000 | K45: 8 | L45: 6 | M45: 4 | N45: 0 | O45: 3 | P45: 1
B46: Project F | C46: 45931 | D46: 45852 | E46: 46042 | F46: =E46-D46 -> 190 | G46: 5 | H46: 123400 | I46: 125000 | J46: =(H46-I46) -> -1600 | K46: 5 | L46: 0 | M46: 0 | N46: 2 | O46: 0 | P46: 2
B47: Project G | C47: 45962 | D47: 45870 | E47: 45931 | F47: =E47-D47 -> 61 | G47: 10 | H47: 250500 | I47: 246000 | J47: =(H47-I47) -> 4500 | K47: 6 | L47: 4 | M47: 0 | N47: 1 | O47: 2 | P47: 3
B48: Project H | C48: 45992 | D48: 45883 | E48: 45899 | F48: =E48-D48 -> 16 | G48: 5 | H48: 127200 | I48: 126000 | J48: =(H48-I48) -> 1200 | K48: 7 | L48: 3 | M48: 3 | N48: 0 | O48: 1 | P48: 4
B49: Project J | C49: 46023 | D49: 45901 | E49: 46001 | F49: =E49-D49 -> 100 | G49: 10 | H49: 80000 | I49: 79900 | J49: =(H49-I49) -> 100 | K49: 0 | L49: 2 | M49: 4 | N49: 1 | O49: 3 | P49: 2
B50: Project K | C50: 46054 | D50: 45931 | E50: 45976 | F50: =E50-D50 -> 45 | G50: 5 | H50: 77000 | I50: 77000 | J50: =(H50-I50) -> 0 | K50: 4 | L50: 4 | M50: 5 | N50: 2 | O50: 0 | P50: 0
B51: Project L | C51: 46082 | D51: 45931 | E51: 45992 | F51: =E51-D51 -> 61 | G51: 10 | H51: 65000 | I51: 65000 | J51: =(H51-I51) -> 0 | K51: 3 | L51: 6 | M51: 4 | N51: 3 | O51: 2 | P51: 0
B52: Project M | C52: 46113 | D52: 45962 | E52: 45992 | F52: =E52-D52 -> 30 | G52: 5 | H52: 550000 | I52: 551000 | J52: =(H52-I52) -> -1000 | K52: 2 | L52: 3 | M52: 6 | N52: 0 | O52: 1 | P52: 1
... B54: Project P | C54: 46174 | D54: 45992 | E54: 46063 | F54: =E54-D54 -> 71 | G54: 5 | H54: 32500 | I54: 33000 | J54: =(H54-I54) -> -500 | K54: 5 | L54: 0 | M54: 2 | N54: 2 | O54: 1 | P54: 3
H55: =SUM(H41:H54) -> 5404600 | I55: =SUM(I41:I54) -> 5272950 | J55: =SUM(J41:J54) -> 131650 | K55: =SUM(K41:K54) -> 52 | L55: =SUM(L41:L54) -> 44 | M55: =SUM(M41:M54) -> 48 | N55: =SUM(N41:N54) -> 18 | O55: =SUM(O41:O54) -> 16 | P55: =SUM(P41:P54) -> 27
B57: CLICK HERE TO CREATE IN SMARTSHEET

Sheet – Disclaimer –
B2: Any articles, templates, or information provided by Smartsheet on the website are for reference only. While we strive to keep the information up to date and correct, we make no representations or warranties of any kind, express or implied, about the completeness, accuracy, reliability, suitability, or availability with respect to the website or the information, articles, templates, or related graphics contained on the website. Any reliance you place on such information is therefore strictly at your own risk.

Sheet Ticket Issue Client Dashboard
B1: Maintenance Client Issue Dashboard Tracking 30/06/2026
B3: CONTRACT PERIOD
B6: Issue by Clients
B11: SLA EXCEED BY CLIENTS
B17: DASHBOARD DATA | G17: **Delete unused rows to correctly populate charts and graphs, above.
B18: PROJECT NAME | C18: CONTRACT DATE | G18: TOTAL TICKETS | H18: FAILED SLA | K18: OPEN | M18: COMPLETED / CLOSED
C19: CALENDAR | D19: BEGIN | E19: FINISH | F19: # of DAYS | H19: 1-30 DAYS | I19: 31-60 DAYS | J19: > 60 DAYS | K19: INPROGRESS | L19: PENDING
B20: FRIM | C20: 46023 | D20: 46023 | E20: 46387 | F20: =E20-D20+1 -> 365 | G20: =FRIM!C1 -> 104 | H20: =FRIM!T9 -> 7 | I20: =FRIM!U9 -> 6 | J20: =FRIM!V9 -> 17 | K20: =FRIM!T4 -> 0 | L20: =FRIM!T3 -> 30 | M20: =FRIM!G1 -> 74
B21: MTIB | C21: 46023 | D21: 45962 | E21: 46326 | F21: =E21-D21+1 -> 365 | G21: =MTIB!C1 -> 52 | H21: =MTIB!T9 -> 2 | I21: =MTIB!U9 -> 6 | J21: =MTIB!V9 -> 7 | K21: =MTIB!T4 -> 1 | L21: =MTIB!T3 -> 15 | M21: =MTIB!G1 -> 36
B22: MPOB | C22: 46023 | D22: 46023 | E22: 46387 | F22: =E22-D22+1 -> 365 | G22: =MPOB!C1 -> 206 | H22: =MPOB!T9 -> 0 | I22: =MPOB!U9 -> 11 | J22: =MPOB!V9 -> 26 | K22: =MPOB!T4 -> 9 | L22: =MPOB!T3 -> 29 | M22: =MPOB!G1 -> 168
B23: LKTN | C23: 46023 | D23: 46023 | E23: 46387 | F23: =E23-D23+1 -> 365 | G23: =LKTN!C1 -> 15 | H23: =LKTN!T9 -> 2 | I23: =LKTN!U9 -> 2 | J23: =LKTN!V9 -> 0 | K23: =LKTN!T4 -> 0 | L23: =LKTN!T3 -> 4 | M23: =LKTN!G1 -> 11
B24: LAM | C24: 45931 | D24: 45931 | E24: 46295 | F24: =E24-D24+1 -> 365 | G24: =LAM!C1 -> 21 | H24: =LAM!T9 -> 1 | I24: =LAM!U9 -> 2 | J24: =LAM!V9 -> 1 | K24: =LAM!T4 -> 0 | L24: =LAM!T3 -> 4 | M24: =LAM!G1 -> 17
B25: ISN | C25: 46023 | D25: 46023 | E25: 46387 | F25: =E25-D25+1 -> 365 | G25: =ISN!C1 -> 25 | H25: =ISN!T9 -> 6 | I25: =ISN!U9 -> 1 | J25: =ISN!V9 -> 2 | K25: =ISN!T4 -> 2 | L25: =ISN!T3 -> 7 | M25: =ISN!G1 -> 16
B26: MSN | C26: 46023 | D26: 45809 | E26: 46173 | F26: =E26-D26+1 -> 365 | G26: =MSN!C1 -> 9 | H26: =MSN!T9 -> 0 | I26: =MSN!U9 -> 0 | J26: =MSN!V9 -> 3 | K26: =MSN!T4 -> 1 | L26: =MSN!T3 -> 2 | M26: =MSN!G1 -> 6
C27: 46023 | D27: 46023 | E27: 46387 | F27: =E27-D27+1 -> 365 | G27: 0 | H27: 0 | I27: 0 | J27: 0 | K27: 0 | L27: 0 | M27: 0
B28: KHTP (KTPC) | C28: 46023 | D28: 45927 | E28: 46291 | F28: =E28-D28+1 -> 365 | G28: =KTPC!C1 -> 9 | H28: =KTPC!T9 -> 0 | I28: =KTPC!U9 -> 0 | J28: =KTPC!V9 -> 0 | K28: =KTPC!T4 -> 0 | L28: =KTPC!T3 -> 0 | M28: =KTPC!G1 -> 9
B29: KUIPS (Warranty) | C29: 46023 | D29: 46023 | E29: 46752 | F29: =E29-D29+1 -> 730 | G29: =KUIPS!C1 -> 32 | H29: =KUIPS!T9 -> 23 | I29: =KUIPS!U9 -> 0 | J29: =KUIPS!V9 -> 0 | K29: =KUIPS!T4 -> 0 | L29: =KUIPS!T3 -> 23 | M29: =KUIPS!G1 -> 9
F30: =E30-D30+1 -> 1
F31: =E31-D31+1 -> 1
F32: =E32-D32+1 -> 1
F33: =E33-D33+1 -> 1
H34: =SUM(H20:H33) -> 41 | I34: =SUM(I20:I33) -> 28 | J34: =SUM(J20:J33) -> 56 | K34: =SUM(K20:K33) -> 13 | L34: =SUM(L20:L33) -> 114 | M34: =SUM(M20:M33) -> 346
B63: **Enter data in the table beginning on Row 41

Sheet Ageing Issue
A1: No | B1: Company | C1: Ticket No | D1: Project | E1: Ticket Detail | F1: Ageing | H1: No | I1: Company | J1: Ticket No | K1: Project | L1: Ticket Detail | M1: Ageing | O1: No | P1: Company | Q1: Ticket No | R1: Project | S1: Ticket Detail | T1: Ageing | V1: No | W1: Company | X1: Ticket No | Y1: Project | Z1: Ticket Detail | AA1: Ageing | AC1: No | AD1: Company | AE1: Ticket No | AF1: Project | AG1: Ticket Detail | AH1: Ageing | AJ1: No | AK1: Company | AL1: Ticket No | AM1: Project | AN1: Ticket Detail | AO1: Ageing | AQ1: No | AR1: Company | AS1: Ticket No | AT1: Project | AU1: Ticket Detail | AV1: Ageing
A2: 1 | B2: {=IFERROR(INDEX(FRIM!$E$3:$E$1000, SMALL(IF(FRIM!$Q$3:$Q$1000<>"", ROW(FRIM!$Q$3:$Q$1000)-ROW(FRIM!$Q$3)+1), ROWS(A$2:A2))),"")} -> FRIM | C2: {=IFERROR(INDEX(FRIM!$B$3:$B$1000, SMALL(IF(FRIM!$Q$3:$Q$1000<>"", ROW(FRIM!$Q$3:$Q$1000)-ROW(FRIM!$Q$3)+1), ROWS(A$2:A2))),"")} -> T/2026/00060 | D2: {=IFERROR(INDEX(FRIM!$D$3:$D$1000, SMALL(IF(FRIM!$Q$3:$Q$1000<>"", ROW(FRIM!$Q$3:$Q$1000)-ROW(FRIM!$Q$3)+1), ROWS(A$2:A2))),"")} -> MYPROCUREMENT | E2: {=IFERROR(INDEX(FRIM!$G$3:$G$1000, SMALL(IF(FRIM!$Q$3:$Q$1000<>"", ROW(FRIM!$Q$3:$Q$1000)-ROW(FRIM!$Q$3)+1), ROWS(A$2:A2))),"")} -> No Aduan: W2488 Name: NUR SYAQIRAH BINTI MOHAMED FOZI Date: 07/01/2026 Desc: PADA DEFINISI TEMPOH TUTUP RO MOHON UNTUK TUTUP JUGA SISTEM BAGI PELULUS DAN PENYOKONG VOT SEPERTIMANA TEMPOH YANG DITETAPKAN. | F2: {=IFERROR(INDEX(FRIM!$Q$3:$Q$1000, SMALL(IF(FRIM!$Q$3:$Q$1000<>"", ROW(FRIM!$Q$3:$Q$1000)-ROW(FRIM!$Q$3)+1), ROWS(A$2:A2))),"")} -> >60 Days | H2: 1 | I2: {=IFERROR(INDEX(MTIB!$E$3:$E$1000, SMALL( IF((MTIB!$Q$3:$Q$1000<>"")*(MTIB!$Q$3:$Q$1000<>"Not Due"), ROW(MTIB!$Q$3:$Q$1000)-ROW(MTIB!$Q$3)+1), ROWS(A$2:A2))),"")} -> MTIB | J2: {=IFERROR(INDEX(MTIB!$B$3:$B$1000, SMALL( IF((MTIB!$Q$3:$Q$1000<>"")*(MTIB!$Q$3:$Q$1000<>"Not Due"), ROW(MTIB!$Q$3:$Q$1000)-ROW(MTIB!$Q$3)+1), ROWS(A$2:A2))),"")} -> T/2025/00182 | K2: {=IFERROR(INDEX(MTIB!$D$3:$D$1000, SMALL( IF((MTIB!$Q$3:$Q$1000<>"")*(MTIB!$Q$3:$Q$1000<>"Not Due"), ROW(MTIB!$Q$3:$Q$1000)-ROW(MTIB!$Q$3)+1), ROWS(A$2:A2))),"")} -> EFT | L2: {=IFERROR(INDEX(MTIB!$G$3:$G$1000, SMALL( IF((MTIB!$Q$3:$Q$1000<>"")*(MTIB!$Q$3:$Q$1000<>"Not Due"), ROW(MTIB!$Q$3:$Q$1000)-ROW(MTIB!$Q$3)+1), ROWS(A$2:A2))),"")} -> 1. Notifikasi - notis pembayaran melalui EFT tidak diterima oleh pihak pembekal, pegawai projek 2. Notis untuk tuntutan/pendahuluan juga tidak diterima oleh pagawai MTIB Pengadu: Siti Zahrah Senin | M2: {=IFERROR(INDEX(MTIB!$Q$3:$Q$1000, SMALL( IF((MTIB!$Q$3:$Q$1000<>"")*(MTIB!$Q$3:$Q$1000<>"Not Due"), ROW(MTIB!$Q$3:$Q$1000)-ROW(MTIB!$Q$3)+1), ROWS(A$2:A2)) ),"")} -> >60 Days | O2: 1 | P2: {=IFERROR(INDEX(MPOB!$E$3:$E$1000, SMALL( IF((MPOB!$Q$3:$Q$1000<>"")*(MPOB!$Q$3:$Q$1000<>"Not Due"), ROW(MPOB!$Q$3:$Q$1000)-ROW(MPOB!$Q$3)+1), ROWS(A$2:A2))),"")} -> MPOB | Q2: {=IFERROR(INDEX(MPOB!$B$3:$B$1000, SMALL( IF((MPOB!$Q$3:$Q$1000<>"")*(MPOB!$Q$3:$Q$1000<>"Not Due"), ROW(MPOB!$Q$3:$Q$1000)-ROW(MPOB!$Q$3)+1), ROWS(A$2:A2))),"")} -> T/2026/00142 | R2: {=IFERROR(INDEX(MPOB!$D$3:$D$1000, SMALL( IF((MPOB!$Q$3:$Q$1000<>"")*(MPOB!$Q$3:$Q$1000<>"Not Due"), ROW(MPOB!$Q$3:$Q$1000)-ROW(MPOB!$Q$3)+1), ROWS(A$2:A2))),"")} -> MyAsset | S2: {=IFERROR(INDEX(MPOB!$G$3:$G$1000, SMALL( IF((MPOB!$Q$3:$Q$1000<>"")*(MPOB!$Q$3:$Q$1000<>"Not Due"), ROW(MPOB!$Q$3:$Q$1000)-ROW(MPOB!$Q$3)+1), ROWS(A$2:A2))),"")} -> Nama User : Zulaikha Date : 19/1/2026 Isu :Ini berkaitan pendaftaran aset dalam modul MyAsset, PIC sebelum ni Puan Suhana tapi tak sure masih sama atau tidak 👆🏼ni senarai pendaftaran aset yang masih pending peringkat pengesahan dan kelulusan Nak mintak tolong SW semak dan luluskan secara backdoor dan provide kami nombor jurnal AM untuk kami approve Sama seperti tahun lepas, kami terpaksa mintak tolong SW untuk buat backdoor sebab dah terlalu lambat dan pertukaran pegawai aset. | T2: {=IFERROR(INDEX(MPOB!$Q$3:$Q$1000, SMALL( IF((MPOB!$Q$3:$Q$1000<>"")*(MPOB!$Q$3:$Q$1000<>"Not Due"), ROW(MPOB!$Q$3:$Q$1000)-ROW(MPOB!$Q$3)+1), ROWS(A$2:A2)) ),"")} -> >60 Days | V2: 1 | W2: {=IFERROR(INDEX(LKTN!$E$3:$E$1000, SMALL( IF((LKTN!$Q$3:$Q$1000<>"")*(LKTN!$Q$3:$Q$1000<>"Not Due"), ROW(LKTN!$Q$3:$Q$1000)-ROW(LKTN!$Q$3)+1), ROWS(A$2:A2))),"")} -> LKTN | X2: {=IFERROR(INDEX(LKTN!$B$3:$B$1000, SMALL( IF((LKTN!$Q$3:$Q$1000<>"")*(LKTN!$Q$3:$Q$1000<>"Not Due"), ROW(LKTN!$Q$3:$Q$1000)-ROW(LKTN!$Q$3)+1), ROWS(A$2:A2))),"")} -> T/2026/00293 | Y2: {=IFERROR(INDEX(LKTN!$D$3:$D$1000, SMALL( IF((LKTN!$Q$3:$Q$1000<>"")*(LKTN!$Q$3:$Q$1000<>"Not Due"), ROW(LKTN!$Q$3:$Q$1000)-ROW(LKTN!$Q$3)+1), ROWS(A$2:A2))),"")} -> MYPROCUREMENT | Z2: {=IFERROR(INDEX(LKTN!$G$3:$G$1000, SMALL( IF((LKTN!$Q$3:$Q$1000<>"")*(LKTN!$Q$3:$Q$1000<>"Not Due"), ROW(LKTN!$Q$3:$Q$1000)-ROW(LKTN!$Q$3)+1), ROWS(A$2:A2))),"")} -> PEMOHON TIDAK DAPAT MEMBUAT PENGESAHAN PENERIMAAN. RUJUKAN : NO. LO : LO1225/01161 NO. PENERIMAAN : PR005922 | AA2: {=IFERROR(INDEX(LKTN!$Q$3:$Q$1000, SMALL( IF((LKTN!$Q$3:$Q$1000<>"")*(LKTN!$Q$3:$Q$1000<>"Not Due"), ROW(LKTN!$Q$3:$Q$1000)-ROW(LKTN!$Q$3)+1), ROWS(A$2:A2)) ),"")} -> 31-60 Days | AC2: 1 | AD2: {=IFERROR(INDEX(LAM!$E$3:$E$1000, SMALL( IF((LAM!$Q$3:$Q$1000<>"")*(LAM!$Q$3:$Q$1000<>"Not Due"), ROW(LAM!$Q$3:$Q$1000)-ROW(LAM!$Q$3)+1), ROWS(A$2:A2))),"")} -> LAM | AE2: {=IFERROR(INDEX(LAM!$B$3:$B$1000, SMALL( IF((LAM!$Q$3:$Q$1000<>"")*(LAM!$Q$3:$Q$1000<>"Not Due"), ROW(LAM!$Q$3:$Q$1000)-ROW(LAM!$Q$3)+1), ROWS(A$2:A2))),"")} -> T/2026/00245 | AF2: {=IFERROR(INDEX(LAM!$D$3:$D$1000, SMALL( IF((LAM!$Q$3:$Q$1000<>"")*(LAM!$Q$3:$Q$1000<>"Not Due"), ROW(LAM!$Q$3:$Q$1000)-ROW(LAM!$Q$3)+1), ROWS(A$2:A2))),"")} -> MYPANJAR | AG2: {=IFERROR(INDEX(LAM!$G$3:$G$1000, SMALL( IF((LAM!$Q$3:$Q$1000<>"")*(LAM!$Q$3:$Q$1000<>"Not Due"), ROW(LAM!$Q$3:$Q$1000)-ROW(LAM!$Q$3)+1), ROWS(A$2:A2))),"")} -> KELUAR ERROR BILA KLIK BUTANG SIMPAN (PANJAR AM) - SEPERTI DI LAMPIRAN | AH2: {=IFERROR(INDEX(LAM!$Q$3:$Q$1000, SMALL( IF((LAM!$Q$3:$Q$1000<>"")*(LAM!$Q$3:$Q$1000<>"Not Due"), ROW(LAM!$Q$3:$Q$1000)-ROW(LAM!$Q$3)+1), ROWS(A$2:A2)) ),"")} -> >60 Days | AJ2: 1 | AK2: {=IFERROR(INDEX(ISN!$E$3:$E$1000, SMALL( IF((ISN!$Q$3:$Q$1000<>"")*(ISN!$Q$3:$Q$1000<>"Not Due"), ROW(ISN!$Q$3:$Q$1000)-ROW(ISN!$Q$3)+1), ROWS(A$2:A2))),"")} -> ISN | AL2: {=IFERROR(INDEX(ISN!$B$3:$B$1000, SMALL( IF((ISN!$Q$3:$Q$1000<>"")*(ISN!$Q$3:$Q$1000<>"Not Due"), ROW(ISN!$Q$3:$Q$1000)-ROW(ISN!$Q$3)+1), ROWS(A$2:A2))),"")} -> T/2026/00021 | AM2: {=IFERROR(INDEX(ISN!$D$3:$D$1000, SMALL( IF((ISN!$Q$3:$Q$1000<>"")*(ISN!$Q$3:$Q$1000<>"Not Due"), ROW(ISN!$Q$3:$Q$1000)-ROW(ISN!$Q$3)+1), ROWS(A$2:A2))),"")} -> MYFINANCIAL CLIENT | AN2: {=IFERROR(INDEX(ISN!$G$3:$G$1000, SMALL( IF((ISN!$Q$3:$Q$1000<>"")*(ISN!$Q$3:$Q$1000<>"Not Due"), ROW(ISN!$Q$3:$Q$1000)-ROW(ISN!$Q$3)+1), ROWS(A$2:A2))),"")} -> Nama Penerima / Syarikat tak appear dalam Laporan Butiran Lejar Am | AO2: {=IFERROR(INDEX(ISN!$Q$3:$Q$1000, SMALL( IF((ISN!$Q$3:$Q$1000<>"")*(ISN!$Q$3:$Q$1000<>"Not Due"), ROW(ISN!$Q$3:$Q$1000)-ROW(ISN!$Q$3)+1), ROWS(A$2:A2)) ),"")} -> >60 Days | AQ2: 1 | AR2: {=IFERROR(INDEX(MSN!$E$3:$E$1000, SMALL( IF((MSN!$Q$3:$Q$1000<>"")*(MSN!$Q$3:$Q$1000<>"Not Due"), ROW(MSN!$Q$3:$Q$1000)-ROW(MSN!$Q$3)+1), ROWS(A$2:A2))),"")} -> MSN | AS2: {=IFERROR(INDEX(MSN!$B$3:$B$1000, SMALL( IF((MSN!$Q$3:$Q$1000<>"")*(MSN!$Q$3:$Q$1000<>"Not Due"), ROW(MSN!$Q$3:$Q$1000)-ROW(MSN!$Q$3)+1), ROWS(A$2:A2))),"")} -> T/2025/00149 | AT2: {=IFERROR(INDEX(MSN!$D$3:$D$1000, SMALL( IF((MSN!$Q$3:$Q$1000<>"")*(MSN!$Q$3:$Q$1000<>"Not Due"), ROW(MSN!$Q$3:$Q$1000)-ROW(MSN!$Q$3)+1), ROWS(A$2:A2))),"")} -> MYSTOR | AU2: {=IFERROR(INDEX(MSN!$G$3:$G$1000, SMALL( IF((MSN!$Q$3:$Q$1000<>"")*(MSN!$Q$3:$Q$1000<>"Not Due"), ROW(MSN!$Q$3:$Q$1000)-ROW(MSN!$Q$3)+1), ROWS(A$2:A2))),"")} -> Mohon untuk membuat beberapa perubahan di dalam sistem stor. A) Borang Permohonan Stok:- 1. Untuk mengemaskini senarai nama kakitangan Majlis dan Bahagian termasuk list venue-venue sukan MSN 2. Untuk buat drop down list sahaja bagi semua ruang kerana Majlis selalu membuat pertukaran tempat bertugas dan terdapat kenaikan pangkat. 3. Tambah ruang catatan dalam permohonan keluaran stok seperti di dalam Borang Kew p.s 8. Pastikan semasa kew p.s8 dijana, keterangan dalam ruang Catatan turut dicetak. 4. Tambah ruang unit dalam butiran permohonan keluaran stok. | AV2: {=IFERROR(INDEX(MSN!$Q$3:$Q$1000, SMALL( IF((MSN!$Q$3:$Q$1000<>"")*(MSN!$Q$3:$Q$1000<>"Not Due"), ROW(MSN!$Q$3:$Q$1000)-ROW(MSN!$Q$3)+1), ROWS(A$2:A2)) ),"")} -> >60 Days
A3: 2 | B3: {=IFERROR(INDEX(FRIM!$E$3:$E$1000, SMALL(IF(FRIM!$Q$3:$Q$1000<>"", ROW(FRIM!$Q$3:$Q$1000)-ROW(FRIM!$Q$3)+1), ROWS(A$2:A3))),"")} -> FRIM | C3: {=IFERROR(INDEX(FRIM!$B$3:$B$1000, SMALL(IF(FRIM!$Q$3:$Q$1000<>"", ROW(FRIM!$Q$3:$Q$1000)-ROW(FRIM!$Q$3)+1), ROWS(A$2:A3))),"")} -> T/2026/00061 | D3: {=IFERROR(INDEX(FRIM!$D$3:$D$1000, SMALL(IF(FRIM!$Q$3:$Q$1000<>"", ROW(FRIM!$Q$3:$Q$1000)-ROW(FRIM!$Q$3)+1), ROWS(A$2:A3))),"")} -> MYPROCUREMENT | E3: {=IFERROR(INDEX(FRIM!$G$3:$G$1000, SMALL(IF(FRIM!$Q$3:$Q$1000<>"", ROW(FRIM!$Q$3:$Q$1000)-ROW(FRIM!$Q$3)+1), ROWS(A$2:A3))),"")} -> No Aduan: W2489 Name: NUR SYAQIRAH BINTI MOHAMED FOZI Date: 13/01/2026 Desc: PEMBEKAL TIDAK BOLEH UPLOAD DOKUMEN PADA PORTAL PENDAFTARAN PEMBEKAL | F3: {=IFERROR(INDEX(FRIM!$Q$3:$Q$1000, SMALL(IF(FRIM!$Q$3:$Q$1000<>"", ROW(FRIM!$Q$3:$Q$1000)-ROW(FRIM!$Q$3)+1), ROWS(A$2:A3))),"")} -> >60 Days | H3: 2 | I3: {=IFERROR(INDEX(MTIB!$E$3:$E$1000, SMALL( IF((MTIB!$Q$3:$Q$1000<>"")*(MTIB!$Q$3:$Q$1000<>"Not Due"), ROW(MTIB!$Q$3:$Q$1000)-ROW(MTIB!$Q$3)+1), ROWS(A$2:A3))),"")} -> MTIB | J3: {=IFERROR(INDEX(MTIB!$B$3:$B$1000, SMALL( IF((MTIB!$Q$3:$Q$1000<>"")*(MTIB!$Q$3:$Q$1000<>"Not Due"), ROW(MTIB!$Q$3:$Q$1000)-ROW(MTIB!$Q$3)+1), ROWS(A$2:A3))),"")} -> T/2025/00183 | K3: {=IFERROR(INDEX(MTIB!$D$3:$D$1000, SMALL( IF((MTIB!$Q$3:$Q$1000<>"")*(MTIB!$Q$3:$Q$1000<>"Not Due"), ROW(MTIB!$Q$3:$Q$1000)-ROW(MTIB!$Q$3)+1), ROWS(A$2:A3))),"")} -> MYFINANCIAL | L3: {=IFERROR(INDEX(MTIB!$G$3:$G$1000, SMALL( IF((MTIB!$Q$3:$Q$1000<>"")*(MTIB!$Q$3:$Q$1000<>"Not Due"), ROW(MTIB!$Q$3:$Q$1000)-ROW(MTIB!$Q$3)+1), ROWS(A$2:A3))),"")} -> Tidak boleh print baucar bayaran BCOWS0725/00181 Pengadu: Mohamad Azrul Azlan | M3: {=IFERROR(INDEX(MTIB!$Q$3:$Q$1000, SMALL( IF((MTIB!$Q$3:$Q$1000<>"")*(MTIB!$Q$3:$Q$1000<>"Not Due"), ROW(MTIB!$Q$3:$Q$1000)-ROW(MTIB!$Q$3)+1), ROWS(A$2:A3)) ),"")} -> >60 Days | O3: 2 | P3: {=IFERROR(INDEX(MPOB!$E$3:$E$1000, SMALL( IF((MPOB!$Q$3:$Q$1000<>"")*(MPOB!$Q$3:$Q$1000<>"Not Due"), ROW(MPOB!$Q$3:$Q$1000)-ROW(MPOB!$Q$3)+1), ROWS(A$2:A3))),"")} -> MPOB | Q3: {=IFERROR(INDEX(MPOB!$B$3:$B$1000, SMALL( IF((MPOB!$Q$3:$Q$1000<>"")*(MPOB!$Q$3:$Q$1000<>"Not Due"), ROW(MPOB!$Q$3:$Q$1000)-ROW(MPOB!$Q$3)+1), ROWS(A$2:A3))),"")} -> T/2026/00144 | R3: {=IFERROR(INDEX(MPOB!$D$3:$D$1000, SMALL( IF((MPOB!$Q$3:$Q$1000<>"")*(MPOB!$Q$3:$Q$1000<>"Not Due"), ROW(MPOB!$Q$3:$Q$1000)-ROW(MPOB!$Q$3)+1), ROWS(A$2:A3))),"")} -> MyDeposit | S3: {=IFERROR(INDEX(MPOB!$G$3:$G$1000, SMALL( IF((MPOB!$Q$3:$Q$1000<>"")*(MPOB!$Q$3:$Q$1000<>"Not Due"), ROW(MPOB!$Q$3:$Q$1000)-ROW(MPOB!$Q$3)+1), ROWS(A$2:A3))),"")} -> Nama User : Norfauzan Date : 20/1/2026 Isu : boleh tgkkn refund nie ...tk boleh Tarik Dekat baucar..dulu dekat baucar hjg tu ade button integrasi utk refund Tk, dulu dekat baucar...lepas sistem upgrde..trs hilang...sebab sy kena integrasi utk baucar msk ke mylesen | T3: {=IFERROR(INDEX(MPOB!$Q$3:$Q$1000, SMALL( IF((MPOB!$Q$3:$Q$1000<>"")*(MPOB!$Q$3:$Q$1000<>"Not Due"), ROW(MPOB!$Q$3:$Q$1000)-ROW(MPOB!$Q$3)+1), ROWS(A$2:A3)) ),"")} -> >60 Days | V3: 2 | W3: {=IFERROR(INDEX(LKTN!$E$3:$E$1000, SMALL( IF((LKTN!$Q$3:$Q$1000<>"")*(LKTN!$Q$3:$Q$1000<>"Not Due"), ROW(LKTN!$Q$3:$Q$1000)-ROW(LKTN!$Q$3)+1), ROWS(A$2:A3))),"")} -> LKTN | X3: {=IFERROR(INDEX(LKTN!$B$3:$B$1000, SMALL( IF((LKTN!$Q$3:$Q$1000<>"")*(LKTN!$Q$3:$Q$1000<>"Not Due"), ROW(LKTN!$Q$3:$Q$1000)-ROW(LKTN!$Q$3)+1), ROWS(A$2:A3))),"")} -> T/2026/00304 | Y3: {=IFERROR(INDEX(LKTN!$D$3:$D$1000, SMALL( IF((LKTN!$Q$3:$Q$1000<>"")*(LKTN!$Q$3:$Q$1000<>"Not Due"), ROW(LKTN!$Q$3:$Q$1000)-ROW(LKTN!$Q$3)+1), ROWS(A$2:A3))),"")} -> MYFINANCIAL | Z3: {=IFERROR(INDEX(LKTN!$G$3:$G$1000, SMALL( IF((LKTN!$Q$3:$Q$1000<>"")*(LKTN!$Q$3:$Q$1000<>"Not Due"), ROW(LKTN!$Q$3:$Q$1000)-ROW(LKTN!$Q$3)+1), ROWS(A$2:A3))),"")} -> JURNAL NO RUJUKAN : JE25/00143 TELAH BERSTATUS POS TIDAK DAPAT DIBATALKAN KERANA KELUAR ERROR SEPERTI DI LAMPIRAN. | AA3: {=IFERROR(INDEX(LKTN!$Q$3:$Q$1000, SMALL( IF((LKTN!$Q$3:$Q$1000<>"")*(LKTN!$Q$3:$Q$1000<>"Not Due"), ROW(LKTN!$Q$3:$Q$1000)-ROW(LKTN!$Q$3)+1), ROWS(A$2:A3)) ),"")} -> 31-60 Days | AC3: 2 | AD3: {=IFERROR(INDEX(LAM!$E$3:$E$1000, SMALL( IF((LAM!$Q$3:$Q$1000<>"")*(LAM!$Q$3:$Q$1000<>"Not Due"), ROW(LAM!$Q$3:$Q$1000)-ROW(LAM!$Q$3)+1), ROWS(A$2:A3))),"")} -> LAM | AE3: {=IFERROR(INDEX(LAM!$B$3:$B$1000, SMALL( IF((LAM!$Q$3:$Q$1000<>"")*(LAM!$Q$3:$Q$1000<>"Not Due"), ROW(LAM!$Q$3:$Q$1000)-ROW(LAM!$Q$3)+1), ROWS(A$2:A3))),"")} -> T/2026/00267 | AF3: {=IFERROR(INDEX(LAM!$D$3:$D$1000, SMALL( IF((LAM!$Q$3:$Q$1000<>"")*(LAM!$Q$3:$Q$1000<>"Not Due"), ROW(LAM!$Q$3:$Q$1000)-ROW(LAM!$Q$3)+1), ROWS(A$2:A3))),"")} -> MYPANJAR | AG3: {=IFERROR(INDEX(LAM!$G$3:$G$1000, SMALL( IF((LAM!$Q$3:$Q$1000<>"")*(LAM!$Q$3:$Q$1000<>"Not Due"), ROW(LAM!$Q$3:$Q$1000)-ROW(LAM!$Q$3)+1), ROWS(A$2:A3))),"")} -> KELUAR 'INTERNAL SERVER ERROR' APABILA BUAT PEMBATALAN TUNTUTAN DI MYPANJAR | AH3: {=IFERROR(INDEX(LAM!$Q$3:$Q$1000, SMALL( IF((LAM!$Q$3:$Q$1000<>"")*(LAM!$Q$3:$Q$1000<>"Not Due"), ROW(LAM!$Q$3:$Q$1000)-ROW(LAM!$Q$3)+1), ROWS(A$2:A3)) ),"")} -> 31-60 Days | AJ3: 2 | AK3: {=IFERROR(INDEX(ISN!$E$3:$E$1000, SMALL( IF((ISN!$Q$3:$Q$1000<>"")*(ISN!$Q$3:$Q$1000<>"Not Due"), ROW(ISN!$Q$3:$Q$1000)-ROW(ISN!$Q$3)+1), ROWS(A$2:A3))),"")} -> ISN | AL3: {=IFERROR(INDEX(ISN!$B$3:$B$1000, SMALL( IF((ISN!$Q$3:$Q$1000<>"")*(ISN!$Q$3:$Q$1000<>"Not Due"), ROW(ISN!$Q$3:$Q$1000)-ROW(ISN!$Q$3)+1), ROWS(A$2:A3))),"")} -> T/2026/00260 | AM3: {=IFERROR(INDEX(ISN!$D$3:$D$1000, SMALL( IF((ISN!$Q$3:$Q$1000<>"")*(ISN!$Q$3:$Q$1000<>"Not Due"), ROW(ISN!$Q$3:$Q$1000)-ROW(ISN!$Q$3)+1), ROWS(A$2:A3))),"")} -> MYSTOR | AN3: {=IFERROR(INDEX(ISN!$G$3:$G$1000, SMALL( IF((ISN!$Q$3:$Q$1000<>"")*(ISN!$Q$3:$Q$1000<>"Not Due"), ROW(ISN!$Q$3:$Q$1000)-ROW(ISN!$Q$3)+1), ROWS(A$2:A3))),"")} -> Jumlah nilai laporan pengeluaran stok stor farmasi (oktober-disember 2025) tidak selaras dengan Laporan Kedudukan Stok Suku Tahun Keempat 2025 (pada column Pengeluaran Suku Tahun Keempat 2025) | AO3: {=IFERROR(INDEX(ISN!$Q$3:$Q$1000, SMALL( IF((ISN!$Q$3:$Q$1000<>"")*(ISN!$Q$3:$Q$1000<>"Not Due"), ROW(ISN!$Q$3:$Q$1000)-ROW(ISN!$Q$3)+1), ROWS(A$2:A3)) ),"")} -> >60 Days | AQ3: 2 | AR3: {=IFERROR(INDEX(MSN!$E$3:$E$1000, SMALL( IF((MSN!$Q$3:$Q$1000<>"")*(MSN!$Q$3:$Q$1000<>"Not Due"), ROW(MSN!$Q$3:$Q$1000)-ROW(MSN!$Q$3)+1), ROWS(A$2:A3))),"")} -> MSN | AS3: {=IFERROR(INDEX(MSN!$B$3:$B$1000, SMALL( IF((MSN!$Q$3:$Q$1000<>"")*(MSN!$Q$3:$Q$1000<>"Not Due"), ROW(MSN!$Q$3:$Q$1000)-ROW(MSN!$Q$3)+1), ROWS(A$2:A3))),"")} -> T/2025/00194 | AT3: {=IFERROR(INDEX(MSN!$D$3:$D$1000, SMALL( IF((MSN!$Q$3:$Q$1000<>"")*(MSN!$Q$3:$Q$1000<>"Not Due"), ROW(MSN!$Q$3:$Q$1000)-ROW(MSN!$Q$3)+1), ROWS(A$2:A3))),"")} -> MYSTOR | AU3: {=IFERROR(INDEX(MSN!$G$3:$G$1000, SMALL( IF((MSN!$Q$3:$Q$1000<>"")*(MSN!$Q$3:$Q$1000<>"Not Due"), ROW(MSN!$Q$3:$Q$1000)-ROW(MSN!$Q$3)+1), ROWS(A$2:A3))),"")} -> 1. Status Aktif / Aktif - access pegawai stor sahaja. 2. Perubahan unit ukuran boleh diubah sehingga 31.12.2025. 3. Tambah kolum JUMLAH di setiap terimaan stok. 4. Laporan JKPAK - Selepas stok diserahkan ke Stor Unit, ianya tidak akan diambil kira dalam laporan JKPAK. 5. Laporan JKPAK - boleh dipaparkan mengikut stor dan mengikut tahun dengan menggabungkan Stor Utama, Stor Kafe dan Stor Peralatan Sukan. | AV3: {=IFERROR(INDEX(MSN!$Q$3:$Q$1000, SMALL( IF((MSN!$Q$3:$Q$1000<>"")*(MSN!$Q$3:$Q$1000<>"Not Due"), ROW(MSN!$Q$3:$Q$1000)-ROW(MSN!$Q$3)+1), ROWS(A$2:A3)) ),"")} -> >60 Days
A4: 3 | B4: {=IFERROR(INDEX(FRIM!$E$3:$E$1000, SMALL(IF(FRIM!$Q$3:$Q$1000<>"", ROW(FRIM!$Q$3:$Q$1000)-ROW(FRIM!$Q$3)+1), ROWS(A$2:A4))),"")} -> FRIM | C4: {=IFERROR(INDEX(FRIM!$B$3:$B$1000, SMALL(IF(FRIM!$Q$3:$Q$1000<>"", ROW(FRIM!$Q$3:$Q$1000)-ROW(FRIM!$Q$3)+1), ROWS(A$2:A4))),"")} -> T/2026/00075 | D4: {=IFERROR(INDEX(FRIM!$D$3:$D$1000, SMALL(IF(FRIM!$Q$3:$Q$1000<>"", ROW(FRIM!$Q$3:$Q$1000)-ROW(FRIM!$Q$3)+1), ROWS(A$2:A4))),"")} -> MYPROCUREMENT | E4: {=IFERROR(INDEX(FRIM!$G$3:$G$1000, SMALL(IF(FRIM!$Q$3:$Q$1000<>"", ROW(FRIM!$Q$3:$Q$1000)-ROW(FRIM!$Q$3)+1), ROWS(A$2:A4))),"")} -> No Aduan: W2508 Name: AZMEI B. MARZUKI Date: 05/02/2026 Desc: ASSALAM, SAYA TELAH BERI ID & PWORD KEPADA SYKT LECO INSTRUMENT (M) SDN BHD. SELEPAS LOGIN, BUTANG UPLOAD TIDAK ADA DALAM SCREEN MAKLUMAT DOKUMEN. SO PIHAK SYARIKAT TIDAK BOLEH UPLOAD SIJIL2 SYARIKAT. TQ | F4: {=IFERROR(INDEX(FRIM!$Q$3:$Q$1000, SMALL(IF(FRIM!$Q$3:$Q$1000<>"", ROW(FRIM!$Q$3:$Q$1000)-ROW(FRIM!$Q$3)+1), ROWS(A$2:A4))),"")} -> >60 Days | H4: 3 | I4: {=IFERROR(INDEX(MTIB!$E$3:$E$1000, SMALL( IF((MTIB!$Q$3:$Q$1000<>"")*(MTIB!$Q$3:$Q$1000<>"Not Due"), ROW(MTIB!$Q$3:$Q$1000)-ROW(MTIB!$Q$3)+1), ROWS(A$2:A4))),"")} -> MTIB | J4: {=IFERROR(INDEX(MTIB!$B$3:$B$1000, SMALL( IF((MTIB!$Q$3:$Q$1000<>"")*(MTIB!$Q$3:$Q$1000<>"Not Due"), ROW(MTIB!$Q$3:$Q$1000)-ROW(MTIB!$Q$3)+1), ROWS(A$2:A4))),"")} -> T/2025/00193 | K4: {=IFERROR(INDEX(MTIB!$D$3:$D$1000, SMALL( IF((MTIB!$Q$3:$Q$1000<>"")*(MTIB!$Q$3:$Q$1000<>"Not Due"), ROW(MTIB!$Q$3:$Q$1000)-ROW(MTIB!$Q$3)+1), ROWS(A$2:A4))),"")} -> MYFINANCIAL | L4: {=IFERROR(INDEX(MTIB!$G$3:$G$1000, SMALL( IF((MTIB!$Q$3:$Q$1000<>"")*(MTIB!$Q$3:$Q$1000<>"Not Due"), ROW(MTIB!$Q$3:$Q$1000)-ROW(MTIB!$Q$3)+1), ROWS(A$2:A4))),"")} -> Tidak dapat 'simpan' untuk kedua-dua MyFinancial web dan client (lampiran) Pengadu: Nor Hafizah Yusoff | M4: {=IFERROR(INDEX(MTIB!$Q$3:$Q$1000, SMALL( IF((MTIB!$Q$3:$Q$1000<>"")*(MTIB!$Q$3:$Q$1000<>"Not Due"), ROW(MTIB!$Q$3:$Q$1000)-ROW(MTIB!$Q$3)+1), ROWS(A$2:A4)) ),"")} -> >60 Days | O4: 3 | P4: {=IFERROR(INDEX(MPOB!$E$3:$E$1000, SMALL( IF((MPOB!$Q$3:$Q$1000<>"")*(MPOB!$Q$3:$Q$1000<>"Not Due"), ROW(MPOB!$Q$3:$Q$1000)-ROW(MPOB!$Q$3)+1), ROWS(A$2:A4))),"")} -> MPOB | Q4: {=IFERROR(INDEX(MPOB!$B$3:$B$1000, SMALL( IF((MPOB!$Q$3:$Q$1000<>"")*(MPOB!$Q$3:$Q$1000<>"Not Due"), ROW(MPOB!$Q$3:$Q$1000)-ROW(MPOB!$Q$3)+1), ROWS(A$2:A4))),"")} -> T/2026/00145 | R4: {=IFERROR(INDEX(MPOB!$D$3:$D$1000, SMALL( IF((MPOB!$Q$3:$Q$1000<>"")*(MPOB!$Q$3:$Q$1000<>"Not Due"), ROW(MPOB!$Q$3:$Q$1000)-ROW(MPOB!$Q$3)+1), ROWS(A$2:A4))),"")} -> MyFinancial | S4: {=IFERROR(INDEX(MPOB!$G$3:$G$1000, SMALL( IF((MPOB!$Q$3:$Q$1000<>"")*(MPOB!$Q$3:$Q$1000<>"Not Due"), ROW(MPOB!$Q$3:$Q$1000)-ROW(MPOB!$Q$3)+1), ROWS(A$2:A4))),"")} -> Nama User : Tyra Date : 20/1/2026 Isu : sy xleh nk cetak resit ini | T4: {=IFERROR(INDEX(MPOB!$Q$3:$Q$1000, SMALL( IF((MPOB!$Q$3:$Q$1000<>"")*(MPOB!$Q$3:$Q$1000<>"Not Due"), ROW(MPOB!$Q$3:$Q$1000)-ROW(MPOB!$Q$3)+1), ROWS(A$2:A4)) ),"")} -> >60 Days | V4: 3 | W4: {=IFERROR(INDEX(LKTN!$E$3:$E$1000, SMALL( IF((LKTN!$Q$3:$Q$1000<>"")*(LKTN!$Q$3:$Q$1000<>"Not Due"), ROW(LKTN!$Q$3:$Q$1000)-ROW(LKTN!$Q$3)+1), ROWS(A$2:A4))),"")} -> LKTN | X4: {=IFERROR(INDEX(LKTN!$B$3:$B$1000, SMALL( IF((LKTN!$Q$3:$Q$1000<>"")*(LKTN!$Q$3:$Q$1000<>"Not Due"), ROW(LKTN!$Q$3:$Q$1000)-ROW(LKTN!$Q$3)+1), ROWS(A$2:A4))),"")} -> T/2026/00419 | Y4: {=IFERROR(INDEX(LKTN!$D$3:$D$1000, SMALL( IF((LKTN!$Q$3:$Q$1000<>"")*(LKTN!$Q$3:$Q$1000<>"Not Due"), ROW(LKTN!$Q$3:$Q$1000)-ROW(LKTN!$Q$3)+1), ROWS(A$2:A4))),"")} -> MYFINANCIAL | Z4: {=IFERROR(INDEX(LKTN!$G$3:$G$1000, SMALL( IF((LKTN!$Q$3:$Q$1000<>"")*(LKTN!$Q$3:$Q$1000<>"Not Due"), ROW(LKTN!$Q$3:$Q$1000)-ROW(LKTN!$Q$3)+1), ROWS(A$2:A4))),"")} -> TERDAPAT PERBEZAAN AMAUN TUNAI (A11101) PADA LEJAR AM DAN KUNCI KIRA-KIRA SEPERTI BERIKUT : PERBEZAAN AMAUN TUNAI (A11101) DI LEJAR AM DAN KUNCI KIRA-KIRA ADALAH SEBANYAK RM46,279.84. MINTA SEMAK DAN PERBETULKAN AMAUN YANG SEBENAR. | AA4: {=IFERROR(INDEX(LKTN!$Q$3:$Q$1000, SMALL( IF((LKTN!$Q$3:$Q$1000<>"")*(LKTN!$Q$3:$Q$1000<>"Not Due"), ROW(LKTN!$Q$3:$Q$1000)-ROW(LKTN!$Q$3)+1), ROWS(A$2:A4)) ),"")} -> 1-30 Days | AC4: 3 | AD4: {=IFERROR(INDEX(LAM!$E$3:$E$1000, SMALL( IF((LAM!$Q$3:$Q$1000<>"")*(LAM!$Q$3:$Q$1000<>"Not Due"), ROW(LAM!$Q$3:$Q$1000)-ROW(LAM!$Q$3)+1), ROWS(A$2:A4))),"")} -> LAM | AE4: {=IFERROR(INDEX(LAM!$B$3:$B$1000, SMALL( IF((LAM!$Q$3:$Q$1000<>"")*(LAM!$Q$3:$Q$1000<>"Not Due"), ROW(LAM!$Q$3:$Q$1000)-ROW(LAM!$Q$3)+1), ROWS(A$2:A4))),"")} -> T/2026/00270 | AF4: {=IFERROR(INDEX(LAM!$D$3:$D$1000, SMALL( IF((LAM!$Q$3:$Q$1000<>"")*(LAM!$Q$3:$Q$1000<>"Not Due"), ROW(LAM!$Q$3:$Q$1000)-ROW(LAM!$Q$3)+1), ROWS(A$2:A4))),"")} -> MYFINANCIAL | AG4: {=IFERROR(INDEX(LAM!$G$3:$G$1000, SMALL( IF((LAM!$Q$3:$Q$1000<>"")*(LAM!$Q$3:$Q$1000<>"Not Due"), ROW(LAM!$Q$3:$Q$1000)-ROW(LAM!$Q$3)+1), ROWS(A$2:A4))),"")} -> TUKAR NAMA 'PENERIMA' DI BAUCAR MYFINANCIAL SEMASA INTEGRASI DARI MYPANJAR, DARI NAMA AZURA BINTI GHAZALI KE FARAH IZWAH BINTI ALI | AH4: {=IFERROR(INDEX(LAM!$Q$3:$Q$1000, SMALL( IF((LAM!$Q$3:$Q$1000<>"")*(LAM!$Q$3:$Q$1000<>"Not Due"), ROW(LAM!$Q$3:$Q$1000)-ROW(LAM!$Q$3)+1), ROWS(A$2:A4)) ),"")} -> 31-60 Days | AJ4: 3 | AK4: {=IFERROR(INDEX(ISN!$E$3:$E$1000, SMALL( IF((ISN!$Q$3:$Q$1000<>"")*(ISN!$Q$3:$Q$1000<>"Not Due"), ROW(ISN!$Q$3:$Q$1000)-ROW(ISN!$Q$3)+1), ROWS(A$2:A4))),"")} -> ISN | AL4: {=IFERROR(INDEX(ISN!$B$3:$B$1000, SMALL( IF((ISN!$Q$3:$Q$1000<>"")*(ISN!$Q$3:$Q$1000<>"Not Due"), ROW(ISN!$Q$3:$Q$1000)-ROW(ISN!$Q$3)+1), ROWS(A$2:A4))),"")} -> T/2026/00325 | AM4: {=IFERROR(INDEX(ISN!$D$3:$D$1000, SMALL( IF((ISN!$Q$3:$Q$1000<>"")*(ISN!$Q$3:$Q$1000<>"Not Due"), ROW(ISN!$Q$3:$Q$1000)-ROW(ISN!$Q$3)+1), ROWS(A$2:A4))),"")} -> MYFINANCIAL CLIENT | AN4: {=IFERROR(INDEX(ISN!$G$3:$G$1000, SMALL( IF((ISN!$Q$3:$Q$1000<>"")*(ISN!$Q$3:$Q$1000<>"Not Due"), ROW(ISN!$Q$3:$Q$1000)-ROW(ISN!$Q$3)+1), ROWS(A$2:A4))),"")} -> Mohon tambah row bagi keterangan dalam cetakan baucar. tq | AO4: {=IFERROR(INDEX(ISN!$Q$3:$Q$1000, SMALL( IF((ISN!$Q$3:$Q$1000<>"")*(ISN!$Q$3:$Q$1000<>"Not Due"), ROW(ISN!$Q$3:$Q$1000)-ROW(ISN!$Q$3)+1), ROWS(A$2:A4)) ),"")} -> 31-60 Days | AQ4: 3 | AR4: {=IFERROR(INDEX(MSN!$E$3:$E$1000, SMALL( IF((MSN!$Q$3:$Q$1000<>"")*(MSN!$Q$3:$Q$1000<>"Not Due"), ROW(MSN!$Q$3:$Q$1000)-ROW(MSN!$Q$3)+1), ROWS(A$2:A4))),"")} -> MSN | AS4: {=IFERROR(INDEX(MSN!$B$3:$B$1000, SMALL( IF((MSN!$Q$3:$Q$1000<>"")*(MSN!$Q$3:$Q$1000<>"Not Due"), ROW(MSN!$Q$3:$Q$1000)-ROW(MSN!$Q$3)+1), ROWS(A$2:A4))),"")} -> T/2026/00238 | AT4: {=IFERROR(INDEX(MSN!$D$3:$D$1000, SMALL( IF((MSN!$Q$3:$Q$1000<>"")*(MSN!$Q$3:$Q$1000<>"Not Due"), ROW(MSN!$Q$3:$Q$1000)-ROW(MSN!$Q$3)+1), ROWS(A$2:A4))),"")} -> ATK | AU4: {=IFERROR(INDEX(MSN!$G$3:$G$1000, SMALL( IF((MSN!$Q$3:$Q$1000<>"")*(MSN!$Q$3:$Q$1000<>"Not Due"), ROW(MSN!$Q$3:$Q$1000)-ROW(MSN!$Q$3)+1), ROWS(A$2:A4))),"")} -> 1. Urus setia telah memeriksa rekod pengeluaran sehingga rekod awal. Terdapat stok yang tiada penerimaan (pertambahan baki) tapi pengeluaran melebihi baki menyebabkan rekod stok menjadi negatif. 2. Pengeluaran dibuat, tiada penolakan baki tetapi ada rekod pengeluaran. 3. Rekod pengeluaran tidak dibuat mengikut pekeliling iaitu 'Masuk Dahulu, Keluar Dahulu' kerana urus setia dapati terdapat 2 rekod bagi suatu 1 item dengan harga yang berlainan dan setiap harga mempunyai baki. Contoh : Sampul surat saiz 6x9 09/05/2023 = 20 kotak x rm 158.80 16/07/2025 = 2 kotak x rm 78.00 | AV4: {=IFERROR(INDEX(MSN!$Q$3:$Q$1000, SMALL( IF((MSN!$Q$3:$Q$1000<>"")*(MSN!$Q$3:$Q$1000<>"Not Due"), ROW(MSN!$Q$3:$Q$1000)-ROW(MSN!$Q$3)+1), ROWS(A$2:A4)) ),"")} -> >60 Days
A5: 4 | B5: {=IFERROR(INDEX(FRIM!$E$3:$E$1000, SMALL(IF(FRIM!$Q$3:$Q$1000<>"", ROW(FRIM!$Q$3:$Q$1000)-ROW(FRIM!$Q$3)+1), ROWS(A$2:A5))),"")} -> FRIM | C5: {=IFERROR(INDEX(FRIM!$B$3:$B$1000, SMALL(IF(FRIM!$Q$3:$Q$1000<>"", ROW(FRIM!$Q$3:$Q$1000)-ROW(FRIM!$Q$3)+1), ROWS(A$2:A5))),"")} -> T/2026/00076 | D5: {=IFERROR(INDEX(FRIM!$D$3:$D$1000, SMALL(IF(FRIM!$Q$3:$Q$1000<>"", ROW(FRIM!$Q$3:$Q$1000)-ROW(FRIM!$Q$3)+1), ROWS(A$2:A5))),"")} -> MYFINANCIAL CLIENT | E5: {=IFERROR(INDEX(FRIM!$G$3:$G$1000, SMALL(IF(FRIM!$Q$3:$Q$1000<>"", ROW(FRIM!$Q$3:$Q$1000)-ROW(FRIM!$Q$3)+1), ROWS(A$2:A5))),"")} -> No Aduan: W2509 Name: HASRINA HASNOR BT. KAMARUZAMAN Date: 06/02/2026 Desc: CETAKAN RESIT & LAPORAN 7260182 - SETTING LARI | F5: {=IFERROR(INDEX(FRIM!$Q$3:$Q$1000, SMALL(IF(FRIM!$Q$3:$Q$1000<>"", ROW(FRIM!$Q$3:$Q$1000)-ROW(FRIM!$Q$3)+1), ROWS(A$2:A5))),"")} -> >60 Days | H5: 4 | I5: {=IFERROR(INDEX(MTIB!$E$3:$E$1000, SMALL( IF((MTIB!$Q$3:$Q$1000<>"")*(MTIB!$Q$3:$Q$1000<>"Not Due"), ROW(MTIB!$Q$3:$Q$1000)-ROW(MTIB!$Q$3)+1), ROWS(A$2:A5))),"")} -> MTIB | J5: {=IFERROR(INDEX(MTIB!$B$3:$B$1000, SMALL( IF((MTIB!$Q$3:$Q$1000<>"")*(MTIB!$Q$3:$Q$1000<>"Not Due"), ROW(MTIB!$Q$3:$Q$1000)-ROW(MTIB!$Q$3)+1), ROWS(A$2:A5))),"")} -> T/2025/00198 | K5: {=IFERROR(INDEX(MTIB!$D$3:$D$1000, SMALL( IF((MTIB!$Q$3:$Q$1000<>"")*(MTIB!$Q$3:$Q$1000<>"Not Due"), ROW(MTIB!$Q$3:$Q$1000)-ROW(MTIB!$Q$3)+1), ROWS(A$2:A5))),"")} -> MYLOAN | L5: {=IFERROR(INDEX(MTIB!$G$3:$G$1000, SMALL( IF((MTIB!$Q$3:$Q$1000<>"")*(MTIB!$Q$3:$Q$1000<>"Not Due"), ROW(MTIB!$Q$3:$Q$1000)-ROW(MTIB!$Q$3)+1), ROWS(A$2:A5))),"")} -> Tiada fungsi hapus atau roles dibenarkan kepada Nor Atikah (PSM) untuk hapus permohonan/rekod Nurul Iman seperti di lampiran kerana pemohon tak jadi mohon pinjaman. | M5: {=IFERROR(INDEX(MTIB!$Q$3:$Q$1000, SMALL( IF((MTIB!$Q$3:$Q$1000<>"")*(MTIB!$Q$3:$Q$1000<>"Not Due"), ROW(MTIB!$Q$3:$Q$1000)-ROW(MTIB!$Q$3)+1), ROWS(A$2:A5)) ),"")} -> >60 Days | O5: 4 | P5: {=IFERROR(INDEX(MPOB!$E$3:$E$1000, SMALL( IF((MPOB!$Q$3:$Q$1000<>"")*(MPOB!$Q$3:$Q$1000<>"Not Due"), ROW(MPOB!$Q$3:$Q$1000)-ROW(MPOB!$Q$3)+1), ROWS(A$2:A5))),"")} -> MPOB | Q5: {=IFERROR(INDEX(MPOB!$B$3:$B$1000, SMALL( IF((MPOB!$Q$3:$Q$1000<>"")*(MPOB!$Q$3:$Q$1000<>"Not Due"), ROW(MPOB!$Q$3:$Q$1000)-ROW(MPOB!$Q$3)+1), ROWS(A$2:A5))),"")} -> T/2026/00146 | R5: {=IFERROR(INDEX(MPOB!$D$3:$D$1000, SMALL( IF((MPOB!$Q$3:$Q$1000<>"")*(MPOB!$Q$3:$Q$1000<>"Not Due"), ROW(MPOB!$Q$3:$Q$1000)-ROW(MPOB!$Q$3)+1), ROWS(A$2:A5))),"")} -> Projek Kos | S5: {=IFERROR(INDEX(MPOB!$G$3:$G$1000, SMALL( IF((MPOB!$Q$3:$Q$1000<>"")*(MPOB!$Q$3:$Q$1000<>"Not Due"), ROW(MPOB!$Q$3:$Q$1000)-ROW(MPOB!$Q$3)+1), ROWS(A$2:A5))),"")} -> Nama User : Khairun nisa Date : 20/1/2026 Isu : Ada amaun negatif. | T5: {=IFERROR(INDEX(MPOB!$Q$3:$Q$1000, SMALL( IF((MPOB!$Q$3:$Q$1000<>"")*(MPOB!$Q$3:$Q$1000<>"Not Due"), ROW(MPOB!$Q$3:$Q$1000)-ROW(MPOB!$Q$3)+1), ROWS(A$2:A5)) ),"")} -> >60 Days | V5: 4 | W5: {=IFERROR(INDEX(LKTN!$E$3:$E$1000, SMALL( IF((LKTN!$Q$3:$Q$1000<>"")*(LKTN!$Q$3:$Q$1000<>"Not Due"), ROW(LKTN!$Q$3:$Q$1000)-ROW(LKTN!$Q$3)+1), ROWS(A$2:A5))),"")} -> LKTN | X5: {=IFERROR(INDEX(LKTN!$B$3:$B$1000, SMALL( IF((LKTN!$Q$3:$Q$1000<>"")*(LKTN!$Q$3:$Q$1000<>"Not Due"), ROW(LKTN!$Q$3:$Q$1000)-ROW(LKTN!$Q$3)+1), ROWS(A$2:A5))),"")} -> T/2026/00455 | Y5: {=IFERROR(INDEX(LKTN!$D$3:$D$1000, SMALL( IF((LKTN!$Q$3:$Q$1000<>"")*(LKTN!$Q$3:$Q$1000<>"Not Due"), ROW(LKTN!$Q$3:$Q$1000)-ROW(LKTN!$Q$3)+1), ROWS(A$2:A5))),"")} -> MYSTOR | Z5: {=IFERROR(INDEX(LKTN!$G$3:$G$1000, SMALL( IF((LKTN!$Q$3:$Q$1000<>"")*(LKTN!$Q$3:$Q$1000<>"Not Due"), ROW(LKTN!$Q$3:$Q$1000)-ROW(LKTN!$Q$3)+1), ROWS(A$2:A5))),"")} -> Staf Yang Tidak Dapat Membuat Permohonan Dalam Mystore 1. Muhamad Najib Bin Daud 2. Hafizi Bin Hashim 3. Muhamad Rozaidi Bin Shafie 4. Muhamad Zaini Bin Abdul Ghani 5. Ahmad Syahmi Bin Ismail Nasharuddin Berikan Akses sebagai Pegawai Stor 1. Mohd Khairi Bin Yusoff | AA5: {=IFERROR(INDEX(LKTN!$Q$3:$Q$1000, SMALL( IF((LKTN!$Q$3:$Q$1000<>"")*(LKTN!$Q$3:$Q$1000<>"Not Due"), ROW(LKTN!$Q$3:$Q$1000)-ROW(LKTN!$Q$3)+1), ROWS(A$2:A5)) ),"")} -> 1-30 Days | AC5: 4 | AD5: {=IFERROR(INDEX(LAM!$E$3:$E$1000, SMALL( IF((LAM!$Q$3:$Q$1000<>"")*(LAM!$Q$3:$Q$1000<>"Not Due"), ROW(LAM!$Q$3:$Q$1000)-ROW(LAM!$Q$3)+1), ROWS(A$2:A5))),"")} -> LAM | AE5: {=IFERROR(INDEX(LAM!$B$3:$B$1000, SMALL( IF((LAM!$Q$3:$Q$1000<>"")*(LAM!$Q$3:$Q$1000<>"Not Due"), ROW(LAM!$Q$3:$Q$1000)-ROW(LAM!$Q$3)+1), ROWS(A$2:A5))),"")} -> T/2026/00452 | AF5: {=IFERROR(INDEX(LAM!$D$3:$D$1000, SMALL( IF((LAM!$Q$3:$Q$1000<>"")*(LAM!$Q$3:$Q$1000<>"Not Due"), ROW(LAM!$Q$3:$Q$1000)-ROW(LAM!$Q$3)+1), ROWS(A$2:A5))),"")} -> MYFINANCIAL | AG5: {=IFERROR(INDEX(LAM!$G$3:$G$1000, SMALL( IF((LAM!$Q$3:$Q$1000<>"")*(LAM!$Q$3:$Q$1000<>"Not Due"), ROW(LAM!$Q$3:$Q$1000)-ROW(LAM!$Q$3)+1), ROWS(A$2:A5))),"")} -> Tiada amaun keluar di Penyata Aliran Tunai bagi tahun 2025 Laporan MPSAS --> Laporan Aliran Tunai --> 2025 | AH5: {=IFERROR(INDEX(LAM!$Q$3:$Q$1000, SMALL( IF((LAM!$Q$3:$Q$1000<>"")*(LAM!$Q$3:$Q$1000<>"Not Due"), ROW(LAM!$Q$3:$Q$1000)-ROW(LAM!$Q$3)+1), ROWS(A$2:A5)) ),"")} -> 1-30 Days | AJ5: 4 | AK5: {=IFERROR(INDEX(ISN!$E$3:$E$1000, SMALL( IF((ISN!$Q$3:$Q$1000<>"")*(ISN!$Q$3:$Q$1000<>"Not Due"), ROW(ISN!$Q$3:$Q$1000)-ROW(ISN!$Q$3)+1), ROWS(A$2:A5))),"")} -> ISN | AL5: {=IFERROR(INDEX(ISN!$B$3:$B$1000, SMALL( IF((ISN!$Q$3:$Q$1000<>"")*(ISN!$Q$3:$Q$1000<>"Not Due"), ROW(ISN!$Q$3:$Q$1000)-ROW(ISN!$Q$3)+1), ROWS(A$2:A5))),"")} -> T/2026/00370 | AM5: {=IFERROR(INDEX(ISN!$D$3:$D$1000, SMALL( IF((ISN!$Q$3:$Q$1000<>"")*(ISN!$Q$3:$Q$1000<>"Not Due"), ROW(ISN!$Q$3:$Q$1000)-ROW(ISN!$Q$3)+1), ROWS(A$2:A5))),"")} -> MYSTOR | AN5: {=IFERROR(INDEX(ISN!$G$3:$G$1000, SMALL( IF((ISN!$Q$3:$Q$1000<>"")*(ISN!$Q$3:$Q$1000<>"Not Due"), ROW(ISN!$Q$3:$Q$1000)-ROW(ISN!$Q$3)+1), ROWS(A$2:A5))),"")} -> MOHON KEMASKINI CHECK & FOUND (PEN MERAH) DI KEWPS.3 SISTEM MYSTORE DALAM STOR FARMASI UNTUK BULAN JUN 2026. | AO5: {=IFERROR(INDEX(ISN!$Q$3:$Q$1000, SMALL( IF((ISN!$Q$3:$Q$1000<>"")*(ISN!$Q$3:$Q$1000<>"Not Due"), ROW(ISN!$Q$3:$Q$1000)-ROW(ISN!$Q$3)+1), ROWS(A$2:A5)) ),"")} -> 1-30 Days | AQ5: 4 | AR5: {=IFERROR(INDEX(MSN!$E$3:$E$1000, SMALL( IF((MSN!$Q$3:$Q$1000<>"")*(MSN!$Q$3:$Q$1000<>"Not Due"), ROW(MSN!$Q$3:$Q$1000)-ROW(MSN!$Q$3)+1), ROWS(A$2:A5))),"")} | AS5: {=IFERROR(INDEX(MSN!$B$3:$B$1000, SMALL( IF((MSN!$Q$3:$Q$1000<>"")*(MSN!$Q$3:$Q$1000<>"Not Due"), ROW(MSN!$Q$3:$Q$1000)-ROW(MSN!$Q$3)+1), ROWS(A$2:A5))),"")} | AT5: {=IFERROR(INDEX(MSN!$D$3:$D$1000, SMALL( IF((MSN!$Q$3:$Q$1000<>"")*(MSN!$Q$3:$Q$1000<>"Not Due"), ROW(MSN!$Q$3:$Q$1000)-ROW(MSN!$Q$3)+1), ROWS(A$2:A5))),"")} | AU5: {=IFERROR(INDEX(MSN!$G$3:$G$1000, SMALL( IF((MSN!$Q$3:$Q$1000<>"")*(MSN!$Q$3:$Q$1000<>"Not Due"), ROW(MSN!$Q$3:$Q$1000)-ROW(MSN!$Q$3)+1), ROWS(A$2:A5))),"")} | AV5: {=IFERROR(INDEX(MSN!$Q$3:$Q$1000, SMALL( IF((MSN!$Q$3:$Q$1000<>"")*(MSN!$Q$3:$Q$1000<>"Not Due"), ROW(MSN!$Q$3:$Q$1000)-ROW(MSN!$Q$3)+1), ROWS(A$2:A5)) ),"")}
A6: 5 | B6: {=IFERROR(INDEX(FRIM!$E$3:$E$1000, SMALL(IF(FRIM!$Q$3:$Q$1000<>"", ROW(FRIM!$Q$3:$Q$1000)-ROW(FRIM!$Q$3)+1), ROWS(A$2:A6))),"")} -> FRIM | C6: {=IFERROR(INDEX(FRIM!$B$3:$B$1000, SMALL(IF(FRIM!$Q$3:$Q$1000<>"", ROW(FRIM!$Q$3:$Q$1000)-ROW(FRIM!$Q$3)+1), ROWS(A$2:A6))),"")} -> T/2026/00078 | D6: {=IFERROR(INDEX(FRIM!$D$3:$D$1000, SMALL(IF(FRIM!$Q$3:$Q$1000<>"", ROW(FRIM!$Q$3:$Q$1000)-ROW(FRIM!$Q$3)+1), ROWS(A$2:A6))),"")} -> QUERY | E6: {=IFERROR(INDEX(FRIM!$G$3:$G$1000, SMALL(IF(FRIM!$Q$3:$Q$1000<>"", ROW(FRIM!$Q$3:$Q$1000)-ROW(FRIM!$Q$3)+1), ROWS(A$2:A6))),"")} -> No Aduan: W2511 Name: NAJWA NAFIAH BINTI FAUZI Date: 12/02/2026 Desc: MOHON BANTUAN SEMAKAN BAGI PEROLEHAN SEPERTI BERIKUT KERANA BERBAKI DEFISIT : 1- AG23017 (TK ELEVATOR MALAYSIA SDN BHD) RM-11.00 2- SHB23002(4/4) (AIRCARBONIC SDN BHD) RM-188.00 3- SHB24004(3)(ALPHA GAS SOLUTION SDN. BHD.) RM- 924.00 4- SH22051 (ABROTECH ENTERPRISE) RM-8,789.40 5- SH24017 (SINAR MESRA SERVICES SDN. BHD.) RM- 30,132.00 | F6: {=IFERROR(INDEX(FRIM!$Q$3:$Q$1000, SMALL(IF(FRIM!$Q$3:$Q$1000<>"", ROW(FRIM!$Q$3:$Q$1000)-ROW(FRIM!$Q$3)+1), ROWS(A$2:A6))),"")} -> >60 Days | H6: 5 | I6: {=IFERROR(INDEX(MTIB!$E$3:$E$1000, SMALL( IF((MTIB!$Q$3:$Q$1000<>"")*(MTIB!$Q$3:$Q$1000<>"Not Due"), ROW(MTIB!$Q$3:$Q$1000)-ROW(MTIB!$Q$3)+1), ROWS(A$2:A6))),"")} -> MTIB | J6: {=IFERROR(INDEX(MTIB!$B$3:$B$1000, SMALL( IF((MTIB!$Q$3:$Q$1000<>"")*(MTIB!$Q$3:$Q$1000<>"Not Due"), ROW(MTIB!$Q$3:$Q$1000)-ROW(MTIB!$Q$3)+1), ROWS(A$2:A6))),"")} -> T/2025/00202 | K6: {=IFERROR(INDEX(MTIB!$D$3:$D$1000, SMALL( IF((MTIB!$Q$3:$Q$1000<>"")*(MTIB!$Q$3:$Q$1000<>"Not Due"), ROW(MTIB!$Q$3:$Q$1000)-ROW(MTIB!$Q$3)+1), ROWS(A$2:A6))),"")} -> MYFINANCIAL | L6: {=IFERROR(INDEX(MTIB!$G$3:$G$1000, SMALL( IF((MTIB!$Q$3:$Q$1000<>"")*(MTIB!$Q$3:$Q$1000<>"Not Due"), ROW(MTIB!$Q$3:$Q$1000)-ROW(MTIB!$Q$3)+1), ROWS(A$2:A6))),"")} -> Tidak dapat membuat cetakan terus dari sistem MyFinancial tetapi boleh melalui 'text view'. Namun butiran baucar akan terputus ke baucar seterusnya. Untuk itu setiap baucar perlu diperbetul margin sebelum membuat cetakan. Pengadu: Suhani Hassan | M6: {=IFERROR(INDEX(MTIB!$Q$3:$Q$1000, SMALL( IF((MTIB!$Q$3:$Q$1000<>"")*(MTIB!$Q$3:$Q$1000<>"Not Due"), ROW(MTIB!$Q$3:$Q$1000)-ROW(MTIB!$Q$3)+1), ROWS(A$2:A6)) ),"")} -> >60 Days | O6: 5 | P6: {=IFERROR(INDEX(MPOB!$E$3:$E$1000, SMALL( IF((MPOB!$Q$3:$Q$1000<>"")*(MPOB!$Q$3:$Q$1000<>"Not Due"), ROW(MPOB!$Q$3:$Q$1000)-ROW(MPOB!$Q$3)+1), ROWS(A$2:A6))),"")} -> MPOB | Q6: {=IFERROR(INDEX(MPOB!$B$3:$B$1000, SMALL( IF((MPOB!$Q$3:$Q$1000<>"")*(MPOB!$Q$3:$Q$1000<>"Not Due"), ROW(MPOB!$Q$3:$Q$1000)-ROW(MPOB!$Q$3)+1), ROWS(A$2:A6))),"")} -> T/2026/00147 | R6: {=IFERROR(INDEX(MPOB!$D$3:$D$1000, SMALL( IF((MPOB!$Q$3:$Q$1000<>"")*(MPOB!$Q$3:$Q$1000<>"Not Due"), ROW(MPOB!$Q$3:$Q$1000)-ROW(MPOB!$Q$3)+1), ROWS(A$2:A6))),"")} -> MyFinancial | S6: {=IFERROR(INDEX(MPOB!$G$3:$G$1000, SMALL( IF((MPOB!$Q$3:$Q$1000<>"")*(MPOB!$Q$3:$Q$1000<>"Not Due"), ROW(MPOB!$Q$3:$Q$1000)-ROW(MPOB!$Q$3)+1), ROWS(A$2:A6))),"")} -> Nama User : Dalillah Date : 20/1/2026 Isu : Sistem error message | T6: {=IFERROR(INDEX(MPOB!$Q$3:$Q$1000, SMALL( IF((MPOB!$Q$3:$Q$1000<>"")*(MPOB!$Q$3:$Q$1000<>"Not Due"), ROW(MPOB!$Q$3:$Q$1000)-ROW(MPOB!$Q$3)+1), ROWS(A$2:A6)) ),"")} -> >60 Days | V6: 5 | W6: {=IFERROR(INDEX(LKTN!$E$3:$E$1000, SMALL( IF((LKTN!$Q$3:$Q$1000<>"")*(LKTN!$Q$3:$Q$1000<>"Not Due"), ROW(LKTN!$Q$3:$Q$1000)-ROW(LKTN!$Q$3)+1), ROWS(A$2:A6))),"")} | X6: {=IFERROR(INDEX(LKTN!$B$3:$B$1000, SMALL( IF((LKTN!$Q$3:$Q$1000<>"")*(LKTN!$Q$3:$Q$1000<>"Not Due"), ROW(LKTN!$Q$3:$Q$1000)-ROW(LKTN!$Q$3)+1), ROWS(A$2:A6))),"")} | Y6: {=IFERROR(INDEX(LKTN!$D$3:$D$1000, SMALL( IF((LKTN!$Q$3:$Q$1000<>"")*(LKTN!$Q$3:$Q$1000<>"Not Due"), ROW(LKTN!$Q$3:$Q$1000)-ROW(LKTN!$Q$3)+1), ROWS(A$2:A6))),"")} | Z6: {=IFERROR(INDEX(LKTN!$G$3:$G$1000, SMALL( IF((LKTN!$Q$3:$Q$1000<>"")*(LKTN!$Q$3:$Q$1000<>"Not Due"), ROW(LKTN!$Q$3:$Q$1000)-ROW(LKTN!$Q$3)+1), ROWS(A$2:A6))),"")} | AA6: {=IFERROR(INDEX(LKTN!$Q$3:$Q$1000, SMALL( IF((LKTN!$Q$3:$Q$1000<>"")*(LKTN!$Q$3:$Q$1000<>"Not Due"), ROW(LKTN!$Q$3:$Q$1000)-ROW(LKTN!$Q$3)+1), ROWS(A$2:A6)) ),"")} | AC6: 5 | AD6: {=IFERROR(INDEX(LAM!$E$3:$E$1000, SMALL( IF((LAM!$Q$3:$Q$1000<>"")*(LAM!$Q$3:$Q$1000<>"Not Due"), ROW(LAM!$Q$3:$Q$1000)-ROW(LAM!$Q$3)+1), ROWS(A$2:A6))),"")} | AE6: {=IFERROR(INDEX(LAM!$B$3:$B$1000, SMALL( IF((LAM!$Q$3:$Q$1000<>"")*(LAM!$Q$3:$Q$1000<>"Not Due"), ROW(LAM!$Q$3:$Q$1000)-ROW(LAM!$Q$3)+1), ROWS(A$2:A6))),"")} | AF6: {=IFERROR(INDEX(LAM!$D$3:$D$1000, SMALL( IF((LAM!$Q$3:$Q$1000<>"")*(LAM!$Q$3:$Q$1000<>"Not Due"), ROW(LAM!$Q$3:$Q$1000)-ROW(LAM!$Q$3)+1), ROWS(A$2:A6))),"")} | AG6: {=IFERROR(INDEX(LAM!$G$3:$G$1000, SMALL( IF((LAM!$Q$3:$Q$1000<>"")*(LAM!$Q$3:$Q$1000<>"Not Due"), ROW(LAM!$Q$3:$Q$1000)-ROW(LAM!$Q$3)+1), ROWS(A$2:A6))),"")} | AH6: {=IFERROR(INDEX(LAM!$Q$3:$Q$1000, SMALL( IF((LAM!$Q$3:$Q$1000<>"")*(LAM!$Q$3:$Q$1000<>"Not Due"), ROW(LAM!$Q$3:$Q$1000)-ROW(LAM!$Q$3)+1), ROWS(A$2:A6)) ),"")} | AJ6: 5 | AK6: {=IFERROR(INDEX(ISN!$E$3:$E$1000, SMALL( IF((ISN!$Q$3:$Q$1000<>"")*(ISN!$Q$3:$Q$1000<>"Not Due"), ROW(ISN!$Q$3:$Q$1000)-ROW(ISN!$Q$3)+1), ROWS(A$2:A6))),"")} -> ISN | AL6: {=IFERROR(INDEX(ISN!$B$3:$B$1000, SMALL( IF((ISN!$Q$3:$Q$1000<>"")*(ISN!$Q$3:$Q$1000<>"Not Due"), ROW(ISN!$Q$3:$Q$1000)-ROW(ISN!$Q$3)+1), ROWS(A$2:A6))),"")} -> T/2026/00428 | AM6: {=IFERROR(INDEX(ISN!$D$3:$D$1000, SMALL( IF((ISN!$Q$3:$Q$1000<>"")*(ISN!$Q$3:$Q$1000<>"Not Due"), ROW(ISN!$Q$3:$Q$1000)-ROW(ISN!$Q$3)+1), ROWS(A$2:A6))),"")} -> MYASSET | AN6: {=IFERROR(INDEX(ISN!$G$3:$G$1000, SMALL( IF((ISN!$Q$3:$Q$1000<>"")*(ISN!$Q$3:$Q$1000<>"Not Due"), ROW(ISN!$Q$3:$Q$1000)-ROW(ISN!$Q$3)+1), ROWS(A$2:A6))),"")} -> 1) Selepas daftar pemeriksaan aset, pada sub modul_Cetak Pemeriksaan Aset, tiada maklumat dan tidak dapat pos data. 2) Bila cetak dokumen yang dah siap, pada Bahagian, maklumat tidak keluar/tidak lengkap. | AO6: {=IFERROR(INDEX(ISN!$Q$3:$Q$1000, SMALL( IF((ISN!$Q$3:$Q$1000<>"")*(ISN!$Q$3:$Q$1000<>"Not Due"), ROW(ISN!$Q$3:$Q$1000)-ROW(ISN!$Q$3)+1), ROWS(A$2:A6)) ),"")} -> 1-30 Days | AQ6: 5 | AR6: {=IFERROR(INDEX(MSN!$E$3:$E$1000, SMALL( IF((MSN!$Q$3:$Q$1000<>"")*(MSN!$Q$3:$Q$1000<>"Not Due"), ROW(MSN!$Q$3:$Q$1000)-ROW(MSN!$Q$3)+1), ROWS(A$2:A6))),"")} | AS6: {=IFERROR(INDEX(MSN!$B$3:$B$1000, SMALL( IF((MSN!$Q$3:$Q$1000<>"")*(MSN!$Q$3:$Q$1000<>"Not Due"), ROW(MSN!$Q$3:$Q$1000)-ROW(MSN!$Q$3)+1), ROWS(A$2:A6))),"")} | AT6: {=IFERROR(INDEX(MSN!$D$3:$D$1000, SMALL( IF((MSN!$Q$3:$Q$1000<>"")*(MSN!$Q$3:$Q$1000<>"Not Due"), ROW(MSN!$Q$3:$Q$1000)-ROW(MSN!$Q$3)+1), ROWS(A$2:A6))),"")} | AU6: {=IFERROR(INDEX(MSN!$G$3:$G$1000, SMALL( IF((MSN!$Q$3:$Q$1000<>"")*(MSN!$Q$3:$Q$1000<>"Not Due"), ROW(MSN!$Q$3:$Q$1000)-ROW(MSN!$Q$3)+1), ROWS(A$2:A6))),"")} | AV6: {=IFERROR(INDEX(MSN!$Q$3:$Q$1000, SMALL( IF((MSN!$Q$3:$Q$1000<>"")*(MSN!$Q$3:$Q$1000<>"Not Due"), ROW(MSN!$Q$3:$Q$1000)-ROW(MSN!$Q$3)+1), ROWS(A$2:A6)) ),"")}
A7: 6 | B7: {=IFERROR(INDEX(FRIM!$E$3:$E$1000, SMALL(IF(FRIM!$Q$3:$Q$1000<>"", ROW(FRIM!$Q$3:$Q$1000)-ROW(FRIM!$Q$3)+1), ROWS(A$2:A7))),"")} -> FRIM | C7: {=IFERROR(INDEX(FRIM!$B$3:$B$1000, SMALL(IF(FRIM!$Q$3:$Q$1000<>"", ROW(FRIM!$Q$3:$Q$1000)-ROW(FRIM!$Q$3)+1), ROWS(A$2:A7))),"")} -> T/2026/00087 | D7: {=IFERROR(INDEX(FRIM!$D$3:$D$1000, SMALL(IF(FRIM!$Q$3:$Q$1000<>"", ROW(FRIM!$Q$3:$Q$1000)-ROW(FRIM!$Q$3)+1), ROWS(A$2:A7))),"")} -> MYFINANCIAL CLIENT | E7: {=IFERROR(INDEX(FRIM!$G$3:$G$1000, SMALL(IF(FRIM!$Q$3:$Q$1000<>"", ROW(FRIM!$Q$3:$Q$1000)-ROW(FRIM!$Q$3)+1), ROWS(A$2:A7))),"")} -> NO ADUAN : W2516 TARIKH : 23/02/2026 NAMA : HASRINA HASNOR BT. KAMARUZAMAN UNTUK MAKLUMAN, FRIM AKAN MENGGUNAKAN VIRTUAL ACCOUNT (VA) DARIPADA CIMB BANK, DI MANA NOMBOR AKAUN ADALAH UNIK BAGI SETIAP BAHAGIAN/MAKMAL BAGI MEMUDAHKAN PENGECAMAN TERIMAAN. OLEH ITU, MOHON BANTUAN UNTUK KEMASKINI PILIHAN NOMBOR BANK DALAM INVOICE TERSEBUT. | F7: {=IFERROR(INDEX(FRIM!$Q$3:$Q$1000, SMALL(IF(FRIM!$Q$3:$Q$1000<>"", ROW(FRIM!$Q$3:$Q$1000)-ROW(FRIM!$Q$3)+1), ROWS(A$2:A7))),"")} -> >60 Days | H7: 6 | I7: {=IFERROR(INDEX(MTIB!$E$3:$E$1000, SMALL( IF((MTIB!$Q$3:$Q$1000<>"")*(MTIB!$Q$3:$Q$1000<>"Not Due"), ROW(MTIB!$Q$3:$Q$1000)-ROW(MTIB!$Q$3)+1), ROWS(A$2:A7))),"")} -> MTIB | J7: {=IFERROR(INDEX(MTIB!$B$3:$B$1000, SMALL( IF((MTIB!$Q$3:$Q$1000<>"")*(MTIB!$Q$3:$Q$1000<>"Not Due"), ROW(MTIB!$Q$3:$Q$1000)-ROW(MTIB!$Q$3)+1), ROWS(A$2:A7))),"")} -> T/2026/00020 | K7: {=IFERROR(INDEX(MTIB!$D$3:$D$1000, SMALL( IF((MTIB!$Q$3:$Q$1000<>"")*(MTIB!$Q$3:$Q$1000<>"Not Due"), ROW(MTIB!$Q$3:$Q$1000)-ROW(MTIB!$Q$3)+1), ROWS(A$2:A7))),"")} -> MYFINANCIAL | L7: {=IFERROR(INDEX(MTIB!$G$3:$G$1000, SMALL( IF((MTIB!$Q$3:$Q$1000<>"")*(MTIB!$Q$3:$Q$1000<>"Not Due"), ROW(MTIB!$Q$3:$Q$1000)-ROW(MTIB!$Q$3)+1), ROWS(A$2:A7))),"")} -> Tidak dapat notifikasi emel bagi MyFinancial | M7: {=IFERROR(INDEX(MTIB!$Q$3:$Q$1000, SMALL( IF((MTIB!$Q$3:$Q$1000<>"")*(MTIB!$Q$3:$Q$1000<>"Not Due"), ROW(MTIB!$Q$3:$Q$1000)-ROW(MTIB!$Q$3)+1), ROWS(A$2:A7)) ),"")} -> >60 Days | O7: 6 | P7: {=IFERROR(INDEX(MPOB!$E$3:$E$1000, SMALL( IF((MPOB!$Q$3:$Q$1000<>"")*(MPOB!$Q$3:$Q$1000<>"Not Due"), ROW(MPOB!$Q$3:$Q$1000)-ROW(MPOB!$Q$3)+1), ROWS(A$2:A7))),"")} -> MPOB | Q7: {=IFERROR(INDEX(MPOB!$B$3:$B$1000, SMALL( IF((MPOB!$Q$3:$Q$1000<>"")*(MPOB!$Q$3:$Q$1000<>"Not Due"), ROW(MPOB!$Q$3:$Q$1000)-ROW(MPOB!$Q$3)+1), ROWS(A$2:A7))),"")} -> T/2026/00148 | R7: {=IFERROR(INDEX(MPOB!$D$3:$D$1000, SMALL( IF((MPOB!$Q$3:$Q$1000<>"")*(MPOB!$Q$3:$Q$1000<>"Not Due"), ROW(MPOB!$Q$3:$Q$1000)-ROW(MPOB!$Q$3)+1), ROWS(A$2:A7))),"")} -> MyProcurement | S7: {=IFERROR(INDEX(MPOB!$G$3:$G$1000, SMALL( IF((MPOB!$Q$3:$Q$1000<>"")*(MPOB!$Q$3:$Q$1000<>"Not Due"), ROW(MPOB!$Q$3:$Q$1000)-ROW(MPOB!$Q$3)+1), ROWS(A$2:A7))),"")} -> Nama User : Nabila Date :21/1/2026 Isu : boleh ke nak mintak hapuskan pr ni, 008475? Sebab user salah letak nama utk penyokong dan penyemak. | T7: {=IFERROR(INDEX(MPOB!$Q$3:$Q$1000, SMALL( IF((MPOB!$Q$3:$Q$1000<>"")*(MPOB!$Q$3:$Q$1000<>"Not Due"), ROW(MPOB!$Q$3:$Q$1000)-ROW(MPOB!$Q$3)+1), ROWS(A$2:A7)) ),"")} -> >60 Days | V7: 6 | W7: {=IFERROR(INDEX(LKTN!$E$3:$E$1000, SMALL( IF((LKTN!$Q$3:$Q$1000<>"")*(LKTN!$Q$3:$Q$1000<>"Not Due"), ROW(LKTN!$Q$3:$Q$1000)-ROW(LKTN!$Q$3)+1), ROWS(A$2:A7))),"")} | X7: {=IFERROR(INDEX(LKTN!$B$3:$B$1000, SMALL( IF((LKTN!$Q$3:$Q$1000<>"")*(LKTN!$Q$3:$Q$1000<>"Not Due"), ROW(LKTN!$Q$3:$Q$1000)-ROW(LKTN!$Q$3)+1), ROWS(A$2:A7))),"")} | Y7: {=IFERROR(INDEX(LKTN!$D$3:$D$1000, SMALL( IF((LKTN!$Q$3:$Q$1000<>"")*(LKTN!$Q$3:$Q$1000<>"Not Due"), ROW(LKTN!$Q$3:$Q$1000)-ROW(LKTN!$Q$3)+1), ROWS(A$2:A7))),"")} | Z7: {=IFERROR(INDEX(LKTN!$G$3:$G$1000, SMALL( IF((LKTN!$Q$3:$Q$1000<>"")*(LKTN!$Q$3:$Q$1000<>"Not Due"), ROW(LKTN!$Q$3:$Q$1000)-ROW(LKTN!$Q$3)+1), ROWS(A$2:A7))),"")} | AA7: {=IFERROR(INDEX(LKTN!$Q$3:$Q$1000, SMALL( IF((LKTN!$Q$3:$Q$1000<>"")*(LKTN!$Q$3:$Q$1000<>"Not Due"), ROW(LKTN!$Q$3:$Q$1000)-ROW(LKTN!$Q$3)+1), ROWS(A$2:A7)) ),"")} | AC7: 6 | AD7: {=IFERROR(INDEX(LAM!$E$3:$E$1000, SMALL( IF((LAM!$Q$3:$Q$1000<>"")*(LAM!$Q$3:$Q$1000<>"Not Due"), ROW(LAM!$Q$3:$Q$1000)-ROW(LAM!$Q$3)+1), ROWS(A$2:A7))),"")} | AE7: {=IFERROR(INDEX(LAM!$B$3:$B$1000, SMALL( IF((LAM!$Q$3:$Q$1000<>"")*(LAM!$Q$3:$Q$1000<>"Not Due"), ROW(LAM!$Q$3:$Q$1000)-ROW(LAM!$Q$3)+1), ROWS(A$2:A7))),"")} | AF7: {=IFERROR(INDEX(LAM!$D$3:$D$1000, SMALL( IF((LAM!$Q$3:$Q$1000<>"")*(LAM!$Q$3:$Q$1000<>"Not Due"), ROW(LAM!$Q$3:$Q$1000)-ROW(LAM!$Q$3)+1), ROWS(A$2:A7))),"")} | AG7: {=IFERROR(INDEX(LAM!$G$3:$G$1000, SMALL( IF((LAM!$Q$3:$Q$1000<>"")*(LAM!$Q$3:$Q$1000<>"Not Due"), ROW(LAM!$Q$3:$Q$1000)-ROW(LAM!$Q$3)+1), ROWS(A$2:A7))),"")} | AH7: {=IFERROR(INDEX(LAM!$Q$3:$Q$1000, SMALL( IF((LAM!$Q$3:$Q$1000<>"")*(LAM!$Q$3:$Q$1000<>"Not Due"), ROW(LAM!$Q$3:$Q$1000)-ROW(LAM!$Q$3)+1), ROWS(A$2:A7)) ),"")} | AJ7: 6 | AK7: {=IFERROR(INDEX(ISN!$E$3:$E$1000, SMALL( IF((ISN!$Q$3:$Q$1000<>"")*(ISN!$Q$3:$Q$1000<>"Not Due"), ROW(ISN!$Q$3:$Q$1000)-ROW(ISN!$Q$3)+1), ROWS(A$2:A7))),"")} -> ISN | AL7: {=IFERROR(INDEX(ISN!$B$3:$B$1000, SMALL( IF((ISN!$Q$3:$Q$1000<>"")*(ISN!$Q$3:$Q$1000<>"Not Due"), ROW(ISN!$Q$3:$Q$1000)-ROW(ISN!$Q$3)+1), ROWS(A$2:A7))),"")} -> T/2026/00432 | AM7: {=IFERROR(INDEX(ISN!$D$3:$D$1000, SMALL( IF((ISN!$Q$3:$Q$1000<>"")*(ISN!$Q$3:$Q$1000<>"Not Due"), ROW(ISN!$Q$3:$Q$1000)-ROW(ISN!$Q$3)+1), ROWS(A$2:A7))),"")} -> MYSTOR | AN7: {=IFERROR(INDEX(ISN!$G$3:$G$1000, SMALL( IF((ISN!$Q$3:$Q$1000<>"")*(ISN!$Q$3:$Q$1000<>"Not Due"), ROW(ISN!$Q$3:$Q$1000)-ROW(ISN!$Q$3)+1), ROWS(A$2:A7))),"")} -> KEMASKINI BAKI KEW-PS 3 BAGI TAHUN 2026 UNTUK 155 ITEM YANG TERLIBAT SEPERTI DIBINCANGKAN ANTARA EN. MUHAIMIN DAN EN.NIK TERIMA KASIH. -MUHAIMIN (ISN) | AO7: {=IFERROR(INDEX(ISN!$Q$3:$Q$1000, SMALL( IF((ISN!$Q$3:$Q$1000<>"")*(ISN!$Q$3:$Q$1000<>"Not Due"), ROW(ISN!$Q$3:$Q$1000)-ROW(ISN!$Q$3)+1), ROWS(A$2:A7)) ),"")} -> 1-30 Days | AQ7: 6 | AR7: {=IFERROR(INDEX(MSN!$E$3:$E$1000, SMALL( IF((MSN!$Q$3:$Q$1000<>"")*(MSN!$Q$3:$Q$1000<>"Not Due"), ROW(MSN!$Q$3:$Q$1000)-ROW(MSN!$Q$3)+1), ROWS(A$2:A7))),"")} | AS7: {=IFERROR(INDEX(MSN!$B$3:$B$1000, SMALL( IF((MSN!$Q$3:$Q$1000<>"")*(MSN!$Q$3:$Q$1000<>"Not Due"), ROW(MSN!$Q$3:$Q$1000)-ROW(MSN!$Q$3)+1), ROWS(A$2:A7))),"")} | AT7: {=IFERROR(INDEX(MSN!$D$3:$D$1000, SMALL( IF((MSN!$Q$3:$Q$1000<>"")*(MSN!$Q$3:$Q$1000<>"Not Due"), ROW(MSN!$Q$3:$Q$1000)-ROW(MSN!$Q$3)+1), ROWS(A$2:A7))),"")} | AU7: {=IFERROR(INDEX(MSN!$G$3:$G$1000, SMALL( IF((MSN!$Q$3:$Q$1000<>"")*(MSN!$Q$3:$Q$1000<>"Not Due"), ROW(MSN!$Q$3:$Q$1000)-ROW(MSN!$Q$3)+1), ROWS(A$2:A7))),"")} | AV7: {=IFERROR(INDEX(MSN!$Q$3:$Q$1000, SMALL( IF((MSN!$Q$3:$Q$1000<>"")*(MSN!$Q$3:$Q$1000<>"Not Due"), ROW(MSN!$Q$3:$Q$1000)-ROW(MSN!$Q$3)+1), ROWS(A$2:A7)) ),"")}
A8: 7 | B8: {=IFERROR(INDEX(FRIM!$E$3:$E$1000, SMALL(IF(FRIM!$Q$3:$Q$1000<>"", ROW(FRIM!$Q$3:$Q$1000)-ROW(FRIM!$Q$3)+1), ROWS(A$2:A8))),"")} -> FRIM | C8: {=IFERROR(INDEX(FRIM!$B$3:$B$1000, SMALL(IF(FRIM!$Q$3:$Q$1000<>"", ROW(FRIM!$Q$3:$Q$1000)-ROW(FRIM!$Q$3)+1), ROWS(A$2:A8))),"")} -> T/2026/00093 | D8: {=IFERROR(INDEX(FRIM!$D$3:$D$1000, SMALL(IF(FRIM!$Q$3:$Q$1000<>"", ROW(FRIM!$Q$3:$Q$1000)-ROW(FRIM!$Q$3)+1), ROWS(A$2:A8))),"")} -> MYFINANCIAL CLIENT | E8: {=IFERROR(INDEX(FRIM!$G$3:$G$1000, SMALL(IF(FRIM!$Q$3:$Q$1000<>"", ROW(FRIM!$Q$3:$Q$1000)-ROW(FRIM!$Q$3)+1), ROWS(A$2:A8))),"")} -> W2315 06/03/2024 NORFAZIRA BINTI MUHAMAD PAUZI LO RFQ19011 - DI SISTEM MYQUERY TERDAPAT LEBIHAN BAYARAN SEBANYAK (RM3,791.30) TETAPI DI SISTEM MYFINANCIAL DAN REKOD BAYARAN ADALAH TIDAK MELEBIHI BAYARAN. | F8: {=IFERROR(INDEX(FRIM!$Q$3:$Q$1000, SMALL(IF(FRIM!$Q$3:$Q$1000<>"", ROW(FRIM!$Q$3:$Q$1000)-ROW(FRIM!$Q$3)+1), ROWS(A$2:A8))),"")} -> >60 Days | H8: 7 | I8: {=IFERROR(INDEX(MTIB!$E$3:$E$1000, SMALL( IF((MTIB!$Q$3:$Q$1000<>"")*(MTIB!$Q$3:$Q$1000<>"Not Due"), ROW(MTIB!$Q$3:$Q$1000)-ROW(MTIB!$Q$3)+1), ROWS(A$2:A8))),"")} -> MTIB | J8: {=IFERROR(INDEX(MTIB!$B$3:$B$1000, SMALL( IF((MTIB!$Q$3:$Q$1000<>"")*(MTIB!$Q$3:$Q$1000<>"Not Due"), ROW(MTIB!$Q$3:$Q$1000)-ROW(MTIB!$Q$3)+1), ROWS(A$2:A8))),"")} -> T/2026/00094 | K8: {=IFERROR(INDEX(MTIB!$D$3:$D$1000, SMALL( IF((MTIB!$Q$3:$Q$1000<>"")*(MTIB!$Q$3:$Q$1000<>"Not Due"), ROW(MTIB!$Q$3:$Q$1000)-ROW(MTIB!$Q$3)+1), ROWS(A$2:A8))),"")} -> MYFINANCIAL | L8: {=IFERROR(INDEX(MTIB!$G$3:$G$1000, SMALL( IF((MTIB!$Q$3:$Q$1000<>"")*(MTIB!$Q$3:$Q$1000<>"Not Due"), ROW(MTIB!$Q$3:$Q$1000)-ROW(MTIB!$Q$3)+1), ROWS(A$2:A8))),"")} -> 1. Jumlah tidak sama pada laporan KIRA-KIRA KENA BAYAR (TELAH POS) 2. Invois/ daftar bil menjadi double Pengadu: Siti Zahrah Senin | M8: {=IFERROR(INDEX(MTIB!$Q$3:$Q$1000, SMALL( IF((MTIB!$Q$3:$Q$1000<>"")*(MTIB!$Q$3:$Q$1000<>"Not Due"), ROW(MTIB!$Q$3:$Q$1000)-ROW(MTIB!$Q$3)+1), ROWS(A$2:A8)) ),"")} -> >60 Days | O8: 7 | P8: {=IFERROR(INDEX(MPOB!$E$3:$E$1000, SMALL( IF((MPOB!$Q$3:$Q$1000<>"")*(MPOB!$Q$3:$Q$1000<>"Not Due"), ROW(MPOB!$Q$3:$Q$1000)-ROW(MPOB!$Q$3)+1), ROWS(A$2:A8))),"")} -> MPOB | Q8: {=IFERROR(INDEX(MPOB!$B$3:$B$1000, SMALL( IF((MPOB!$Q$3:$Q$1000<>"")*(MPOB!$Q$3:$Q$1000<>"Not Due"), ROW(MPOB!$Q$3:$Q$1000)-ROW(MPOB!$Q$3)+1), ROWS(A$2:A8))),"")} -> T/2026/00150 | R8: {=IFERROR(INDEX(MPOB!$D$3:$D$1000, SMALL( IF((MPOB!$Q$3:$Q$1000<>"")*(MPOB!$Q$3:$Q$1000<>"Not Due"), ROW(MPOB!$Q$3:$Q$1000)-ROW(MPOB!$Q$3)+1), ROWS(A$2:A8))),"")} -> MyFinancial | S8: {=IFERROR(INDEX(MPOB!$G$3:$G$1000, SMALL( IF((MPOB!$Q$3:$Q$1000<>"")*(MPOB!$Q$3:$Q$1000<>"Not Due"), ROW(MPOB!$Q$3:$Q$1000)-ROW(MPOB!$Q$3)+1), ROWS(A$2:A8))),"")} -> Nama User : Norlizah Date : 21/1/2026 Isu : saya masih tak boleh sahkan ni👆 yg ni pun tak boleh nk sahkan | T8: {=IFERROR(INDEX(MPOB!$Q$3:$Q$1000, SMALL( IF((MPOB!$Q$3:$Q$1000<>"")*(MPOB!$Q$3:$Q$1000<>"Not Due"), ROW(MPOB!$Q$3:$Q$1000)-ROW(MPOB!$Q$3)+1), ROWS(A$2:A8)) ),"")} -> >60 Days | V8: 7 | W8: {=IFERROR(INDEX(LKTN!$E$3:$E$1000, SMALL( IF((LKTN!$Q$3:$Q$1000<>"")*(LKTN!$Q$3:$Q$1000<>"Not Due"), ROW(LKTN!$Q$3:$Q$1000)-ROW(LKTN!$Q$3)+1), ROWS(A$2:A8))),"")} | X8: {=IFERROR(INDEX(LKTN!$B$3:$B$1000, SMALL( IF((LKTN!$Q$3:$Q$1000<>"")*(LKTN!$Q$3:$Q$1000<>"Not Due"), ROW(LKTN!$Q$3:$Q$1000)-ROW(LKTN!$Q$3)+1), ROWS(A$2:A8))),"")} | Y8: {=IFERROR(INDEX(LKTN!$D$3:$D$1000, SMALL( IF((LKTN!$Q$3:$Q$1000<>"")*(LKTN!$Q$3:$Q$1000<>"Not Due"), ROW(LKTN!$Q$3:$Q$1000)-ROW(LKTN!$Q$3)+1), ROWS(A$2:A8))),"")} | Z8: {=IFERROR(INDEX(LKTN!$G$3:$G$1000, SMALL( IF((LKTN!$Q$3:$Q$1000<>"")*(LKTN!$Q$3:$Q$1000<>"Not Due"), ROW(LKTN!$Q$3:$Q$1000)-ROW(LKTN!$Q$3)+1), ROWS(A$2:A8))),"")} | AA8: {=IFERROR(INDEX(LKTN!$Q$3:$Q$1000, SMALL( IF((LKTN!$Q$3:$Q$1000<>"")*(LKTN!$Q$3:$Q$1000<>"Not Due"), ROW(LKTN!$Q$3:$Q$1000)-ROW(LKTN!$Q$3)+1), ROWS(A$2:A8)) ),"")} | AC8: 7 | AD8: {=IFERROR(INDEX(LAM!$E$3:$E$1000, SMALL( IF((LAM!$Q$3:$Q$1000<>"")*(LAM!$Q$3:$Q$1000<>"Not Due"), ROW(LAM!$Q$3:$Q$1000)-ROW(LAM!$Q$3)+1), ROWS(A$2:A8))),"")} | AE8: {=IFERROR(INDEX(LAM!$B$3:$B$1000, SMALL( IF((LAM!$Q$3:$Q$1000<>"")*(LAM!$Q$3:$Q$1000<>"Not Due"), ROW(LAM!$Q$3:$Q$1000)-ROW(LAM!$Q$3)+1), ROWS(A$2:A8))),"")} | AF8: {=IFERROR(INDEX(LAM!$D$3:$D$1000, SMALL( IF((LAM!$Q$3:$Q$1000<>"")*(LAM!$Q$3:$Q$1000<>"Not Due"), ROW(LAM!$Q$3:$Q$1000)-ROW(LAM!$Q$3)+1), ROWS(A$2:A8))),"")} | AG8: {=IFERROR(INDEX(LAM!$G$3:$G$1000, SMALL( IF((LAM!$Q$3:$Q$1000<>"")*(LAM!$Q$3:$Q$1000<>"Not Due"), ROW(LAM!$Q$3:$Q$1000)-ROW(LAM!$Q$3)+1), ROWS(A$2:A8))),"")} | AH8: {=IFERROR(INDEX(LAM!$Q$3:$Q$1000, SMALL( IF((LAM!$Q$3:$Q$1000<>"")*(LAM!$Q$3:$Q$1000<>"Not Due"), ROW(LAM!$Q$3:$Q$1000)-ROW(LAM!$Q$3)+1), ROWS(A$2:A8)) ),"")} | AJ8: 7 | AK8: {=IFERROR(INDEX(ISN!$E$3:$E$1000, SMALL( IF((ISN!$Q$3:$Q$1000<>"")*(ISN!$Q$3:$Q$1000<>"Not Due"), ROW(ISN!$Q$3:$Q$1000)-ROW(ISN!$Q$3)+1), ROWS(A$2:A8))),"")} -> ISN | AL8: {=IFERROR(INDEX(ISN!$B$3:$B$1000, SMALL( IF((ISN!$Q$3:$Q$1000<>"")*(ISN!$Q$3:$Q$1000<>"Not Due"), ROW(ISN!$Q$3:$Q$1000)-ROW(ISN!$Q$3)+1), ROWS(A$2:A8))),"")} -> T/2026/00453 | AM8: {=IFERROR(INDEX(ISN!$D$3:$D$1000, SMALL( IF((ISN!$Q$3:$Q$1000<>"")*(ISN!$Q$3:$Q$1000<>"Not Due"), ROW(ISN!$Q$3:$Q$1000)-ROW(ISN!$Q$3)+1), ROWS(A$2:A8))),"")} -> MYASSET | AN8: {=IFERROR(INDEX(ISN!$G$3:$G$1000, SMALL( IF((ISN!$Q$3:$Q$1000<>"")*(ISN!$Q$3:$Q$1000<>"Not Due"), ROW(ISN!$Q$3:$Q$1000)-ROW(ISN!$Q$3)+1), ROWS(A$2:A8))),"")} -> 1) Pada kad Kew Pa 3 dan 4, Bahagian Pemeriksaan dimohon penambahbaikan seperti berikut:: 1.1) Nama lokasi sama seperi nama pada Bahagian penempatan contoh B-036-Bilik Lily, Psikologi Sukan. 1.2) Status aset dipilih mengikut pekelililing contohnya. sedang digunakan, tidak digunakan, perlu pembaikan dan lain-lain. | AO8: {=IFERROR(INDEX(ISN!$Q$3:$Q$1000, SMALL( IF((ISN!$Q$3:$Q$1000<>"")*(ISN!$Q$3:$Q$1000<>"Not Due"), ROW(ISN!$Q$3:$Q$1000)-ROW(ISN!$Q$3)+1), ROWS(A$2:A8)) ),"")} -> 1-30 Days | AQ8: 7 | AR8: {=IFERROR(INDEX(MSN!$E$3:$E$1000, SMALL( IF((MSN!$Q$3:$Q$1000<>"")*(MSN!$Q$3:$Q$1000<>"Not Due"), ROW(MSN!$Q$3:$Q$1000)-ROW(MSN!$Q$3)+1), ROWS(A$2:A8))),"")} | AS8: {=IFERROR(INDEX(MSN!$B$3:$B$1000, SMALL( IF((MSN!$Q$3:$Q$1000<>"")*(MSN!$Q$3:$Q$1000<>"Not Due"), ROW(MSN!$Q$3:$Q$1000)-ROW(MSN!$Q$3)+1), ROWS(A$2:A8))),"")} | AT8: {=IFERROR(INDEX(MSN!$D$3:$D$1000, SMALL( IF((MSN!$Q$3:$Q$1000<>"")*(MSN!$Q$3:$Q$1000<>"Not Due"), ROW(MSN!$Q$3:$Q$1000)-ROW(MSN!$Q$3)+1), ROWS(A$2:A8))),"")} | AU8: {=IFERROR(INDEX(MSN!$G$3:$G$1000, SMALL( IF((MSN!$Q$3:$Q$1000<>"")*(MSN!$Q$3:$Q$1000<>"Not Due"), ROW(MSN!$Q$3:$Q$1000)-ROW(MSN!$Q$3)+1), ROWS(A$2:A8))),"")} | AV8: {=IFERROR(INDEX(MSN!$Q$3:$Q$1000, SMALL( IF((MSN!$Q$3:$Q$1000<>"")*(MSN!$Q$3:$Q$1000<>"Not Due"), ROW(MSN!$Q$3:$Q$1000)-ROW(MSN!$Q$3)+1), ROWS(A$2:A8)) ),"")}
